Workbook

Sheet ReadMe
A1: ReadMe

Sheet Summary
A1: Schedule | B1: Total Land Occupation (ha·year) | C1: Max Total Area Used (ha)
A2: Schedule_1 | B2: =Schedule_1!$J$37 -> 11353.88 | C2: =Schedule_1!$J$38 -> 354.80874
A3: Schedule_2 | B3: =Schedule_2!$J$37 -> 12252.601 | C3: =Schedule_2!$J$38 -> 382.89378
A4: Schedule_3 | B4: =Schedule_3!$J$37 -> 13077.896 | C4: =Schedule_3!$J$38 -> 408.68426
A5: Schedule_4 | B5: =Schedule_4!$J$37 -> 11190.44 | C5: =Schedule_4!$J$38 -> 386.02354
A6: Schedule_5 | B6: =Schedule_5!$J$37 -> 8919.9919 | C6: =Schedule_5!$J$38 -> 356.79967
A7: Schedule_6 | B7: =Schedule_6!$J$37 -> 9990.2866 | C7: =Schedule_6!$J$38 -> 372.03454
A8: Schedule_7 | B8: =Schedule_7!$J$37 -> 10812.052 | C8: =Schedule_7!$J$38 -> 415.84817
A9: Schedule_8 | B9: =Schedule_8!$J$37 -> 10644.676 | C9: =Schedule_8!$J$38 -> 380.16699
A10: Schedule_9 | B10: =Schedule_9!$J$37 -> 11764.403 | C10: =Schedule_9!$J$38 -> 420.15726
A11: Schedule_10 | B11: =Schedule_10!$J$37 -> 11290.734 | C11: =Schedule_10!$J$38 -> 420.55853
A12: Schedule_11 | B12: =Schedule_11!$J$37 -> 8071.1253 | C12: =Schedule_11!$J$38 -> 384.3393
A13: Schedule_12 | B13: =Schedule_12!$J$37 -> 9111.8858 | C13: =Schedule_12!$J$38 -> 342.62491
A14: Schedule_13 | B14: =Schedule_13!$J$37 -> 8411.5527 | C14: =Schedule_13!$J$38 -> 400.55013
A15: Schedule_14 | B15: =Schedule_14!$J$37 -> 11316.412 | C15: =Schedule_14!$J$38 -> 471.51718
A16: Schedule_15 | B16: =Schedule_15!$J$37 -> 13656.532 | C16: =Schedule_15!$J$38 -> 440.53328
A17: Schedule_16 | B17: =Schedule_16!$J$37 -> 8328.9142 | C17: =Schedule_16!$J$38 -> 416.44571
A18: Schedule_17 | B18: =Schedule_17!$J$37 -> 11456.435 | C18: =Schedule_17!$J$38 -> 407.72428
A19: Schedule_18 | B19: =Schedule_18!$J$37 -> 13707.592 | C19: =Schedule_18!$J$38 -> 428.36225
A20: Schedule_19 | B20: =Schedule_19!$J$37 -> 10888.949 | C20: =Schedule_19!$J$38 -> 418.80573
A21: Schedule_20 | B21: =Schedule_20!$J$37 -> 13223.274 | C21: =Schedule_20!$J$38 -> 426.55722
A22: Averages | B22: =AVERAGE(B2:B21) -> 10973.482 | C22: =AVERAGE(C2:C21) -> 401.77177
A23: Total Land Occupation (Sum) | B23: =SUM(B2:B21) -> 219469.63

Sheet Schedule_1
A1: Year | B1: Ore (t) | C1: Waste (t) | D1: Waste (m^3) | E1: Dumps Area (ha) | F1: Leach Facility Area (ha) | G1: Total Material Mined (t) | H1: Cumulative Material (t) | I1: Estimated pit area (ha) | J1: Disturbed Area (ha) | K1: Land Occupation (ha·year)
A2: 1 | B2: 8000000 | C2: 4820712 | D2: =C2/2.5 -> 1928284.8 | E2: =(D2/60)/10000 -> 3.213808 | F2: =(B2*2)/1000000 -> 16 | G2: =IFERROR(B2+C2,0) -> 12820712 | H2: =SUM($G$2:G2) -> 12820712 | I2: =((H2/2.5)/48)/10000 -> 10.683927 | J2: =I2+F2+E2 -> 29.897735 | K2: =A2*J2 -> 29.897735
A3: 2 | B3: 8000000 | C3: 4698275 | D3: =C3/2.5 -> 1879310 | E3: =(D3/60)/10000 -> 3.1321833 | F3: =(B3*2)/1000000 -> 16 | G3: =IFERROR(B3+C3,0) -> 12698275 | H3: =SUM($G$2:G3) -> 25518987 | I3: =((H3/2.5)/48)/10000 -> 21.265823 | J3: =I3+F3+E3 -> 40.398006 | K3: =A3*J3 -> 80.796012
A4: 3 | B4: 8000000 | C4: 4825835 | D4: =C4/2.5 -> 1930334 | E4: =(D4/60)/10000 -> 3.2172233 | F4: =(B4*2)/1000000 -> 16 | G4: =IFERROR(B4+C4,0) -> 12825835 | H4: =SUM($G$2:G4) -> 38344822 | I4: =((H4/2.5)/48)/10000 -> 31.954018 | J4: =I4+F4+E4 -> 51.171242 | K4: =A4*J4 -> 153.51373
A5: 4 | B5: 7746104 | C5: 5253896 | D5: =C5/2.5 -> 2101558.4 | E5: =(D5/60)/10000 -> 3.5025973 | F5: =(B5*2)/1000000 -> 15.492208 | G5: =IFERROR(B5+C5,0) -> 13000000 | H5: =SUM($G$2:G5) -> 51344822 | I5: =((H5/2.5)/48)/10000 -> 42.787352 | J5: =I5+F5+E5 -> 61.782157 | K5: =A5*J5 -> 247.12863
A6: 5 | B6: 7726501 | C6: 5273499 | D6: =C6/2.5 -> 2109399.6 | E6: =(D6/60)/10000 -> 3.515666 | F6: =(B6*2)/1000000 -> 15.453002 | G6: =IFERROR(B6+C6,0) -> 13000000 | H6: =SUM($G$2:G6) -> 64344822 | I6: =((H6/2.5)/48)/10000 -> 53.620685 | J6: =I6+F6+E6 -> 72.589353 | K6: =A6*J6 -> 362.94676
A7: 6 | B7: 7122941 | C7: 5877059 | D7: =C7/2.5 -> 2350823.6 | E7: =(D7/60)/10000 -> 3.9180393 | F7: =(B7*2)/1000000 -> 14.245882 | G7: =IFERROR(B7+C7,0) -> 13000000 | H7: =SUM($G$2:G7) -> 77344822 | I7: =((H7/2.5)/48)/10000 -> 64.454018 | J7: =I7+F7+E7 -> 82.61794 | K7: =A7*J7 -> 495.70764
A8: 7 | B8: 6844616 | C8: 6155384 | D8: =C8/2.5 -> 2462153.6 | E8: =(D8/60)/10000 -> 4.1035893 | F8: =(B8*2)/1000000 -> 13.689232 | G8: =IFERROR(B8+C8,0) -> 13000000 | H8: =SUM($G$2:G8) -> 90344822 | I8: =((H8/2.5)/48)/10000 -> 75.287352 | J8: =I8+F8+E8 -> 93.080173 | K8: =A8*J8 -> 651.56121
A9: 8 | B9: 7836754 | C9: 5163246 | D9: =C9/2.5 -> 2065298.4 | E9: =(D9/60)/10000 -> 3.442164 | F9: =(B9*2)/1000000 -> 15.673508 | G9: =IFERROR(B9+C9,0) -> 13000000 | H9: =SUM($G$2:G9) -> 103344822 | I9: =((H9/2.5)/48)/10000 -> 86.120685 | J9: =I9+F9+E9 -> 105.23636 | K9: =A9*J9 -> 841.89086
A10: 9 | B10: 8000000 | C10: 4172966 | D10: =C10/2.5 -> 1669186.4 | E10: =(D10/60)/10000 -> 2.7819773 | F10: =(B10*2)/1000000 -> 16 | G10: =IFERROR(B10+C10,0) -> 12172966 | H10: =SUM($G$2:G10) -> 115517788 | I10: =((H10/2.5)/48)/10000 -> 96.264823 | J10: =I10+F10+E10 -> 115.0468 | K10: =A10*J10 -> 1035.4212
A11: 10 | B11: 8000000 | C11: 4018384 | D11: =C11/2.5 -> 1607353.6 | E11: =(D11/60)/10000 -> 2.6789227 | F11: =(B11*2)/1000000 -> 16 | G11: =IFERROR(B11+C11,0) -> 12018384 | H11: =SUM($G$2:G11) -> 127536172 | I11: =((H11/2.5)/48)/10000 -> 106.28014 | J11: =I11+F11+E11 -> 124.95907 | K11: =A11*J11 -> 1249.5907
A12: 11 | B12: 8000000 | C12: 3965241 | D12: =C12/2.5 -> 1586096.4 | E12: =(D12/60)/10000 -> 2.643494 | F12: =(B12*2)/1000000 -> 16 | G12: =IFERROR(B12+C12,0) -> 11965241 | H12: =SUM($G$2:G12) -> 139501413 | I12: =((H12/2.5)/48)/10000 -> 116.25118 | J12: =I12+F12+E12 -> 134.89467 | K12: =A12*J12 -> 1483.8414
A13: 12 | B13: 8000000 | C13: 3836277 | D13: =C13/2.5 -> 1534510.8 | E13: =(D13/60)/10000 -> 2.557518 | F13: =(B13*2)/1000000 -> 16 | G13: =IFERROR(B13+C13,0) -> 11836277 | H13: =SUM($G$2:G13) -> 151337690 | I13: =((H13/2.5)/48)/10000 -> 126.11474 | J13: =I13+F13+E13 -> 144.67226 | K13: =A13*J13 -> 1736.0671
... A33: 32 | B33: 4520196 | C33: 6834919 | D33: =C33/2.5 -> 2733967.6 | E33: =(D33/60)/10000 -> 4.5566127 | F33: =(B33*2)/1000000 -> 9.040392 | G33: =IFERROR(B33+C33,0) -> 11355115 | H33: =SUM($G$2:G33) -> 409454080 | I33: =((H33/2.5)/48)/10000 -> 341.21173 | J33: =I33+F33+E33 -> 354.80874 | K33: =A33*J33 -> 11353.88
C35: =SUM(C2:C33) -> 207585280
H37: Key Outputs | I37: Total Land Occupation (ha·year) | J37: =MAX(K2:K33) -> 11353.88
I38: Max Total Area Used (ha) | J38: =MAX(J2:J33) -> 354.80874
G44: Parameters | H44: Units | I44: Value
G45: Haul Road Width | H45: m | I45: 26
G46: Haul Road Gradient | H46: % | I46: 10
G47: Mining Bench Height | H47: m | I47: 10
G48: Safety Berm Width | H48: m | I48: 8
G49: Batter Angle | H49: degrees | I49: 60
G50: Projection Angle | H50: degrees | I50: 18.5
G51: Density | I51: 2.5
G52: Level Height | H52: m | I52: 10
G53: Average dump hieght | H53: m | I53: 60
G54: K_leach | H54: ha per Mt ore | I54: 2
G55: avg. pit depth | H55: m | I55: 48

Sheet Schedule_2
A1: Year | B1: Ore (t) | C1: Waste (t) | D1: Waste (m^3) | E1: Dumps Area (ha) | F1: Leach Facility Area (ha) | G1: Total Material Mined (t) | H1: Cumulative Material (t) | I1: Estimated pit area (ha) | J1: Disturbed Area (ha) | K1: Land Occupation (ha·year)
A2: 1 | B2: 8500000 | C2: 5449307 | D2: =C2/2.5 -> 2179722.8 | E2: =(D2/60)/10000 -> 3.6328713 | F2: =(B2*2)/1000000 -> 17 | G2: =IFERROR(B2+C2,0) -> 13949307 | H2: =SUM($G$2:G2) -> 13949307 | I2: =((H2/2.5)/48)/10000 -> 11.624422 | J2: =I2+F2+E2 -> 32.257294 | K2: =A2*J2 -> 32.257294
A3: 2 | B3: 8500000 | C3: 5039809 | D3: =C3/2.5 -> 2015923.6 | E3: =(D3/60)/10000 -> 3.3598727 | F3: =(B3*2)/1000000 -> 17 | G3: =IFERROR(B3+C3,0) -> 13539809 | H3: =SUM($G$2:G3) -> 27489116 | I3: =((H3/2.5)/48)/10000 -> 22.907597 | J3: =I3+F3+E3 -> 43.267469 | K3: =A3*J3 -> 86.534939
A4: 3 | B4: 8500000 | C4: 5222632 | D4: =C4/2.5 -> 2089052.8 | E4: =(D4/60)/10000 -> 3.4817547 | F4: =(B4*2)/1000000 -> 17 | G4: =IFERROR(B4+C4,0) -> 13722632 | H4: =SUM($G$2:G4) -> 41211748 | I4: =((H4/2.5)/48)/10000 -> 34.343123 | J4: =I4+F4+E4 -> 54.824878 | K4: =A4*J4 -> 164.47463
A5: 4 | B5: 8316331 | C5: 5683669 | D5: =C5/2.5 -> 2273467.6 | E5: =(D5/60)/10000 -> 3.7891127 | F5: =(B5*2)/1000000 -> 16.632662 | G5: =IFERROR(B5+C5,0) -> 14000000 | H5: =SUM($G$2:G5) -> 55211748 | I5: =((H5/2.5)/48)/10000 -> 46.00979 | J5: =I5+F5+E5 -> 66.431565 | K5: =A5*J5 -> 265.72626
A6: 5 | B6: 8199812 | C6: 5800188 | D6: =C6/2.5 -> 2320075.2 | E6: =(D6/60)/10000 -> 3.866792 | F6: =(B6*2)/1000000 -> 16.399624 | G6: =IFERROR(B6+C6,0) -> 14000000 | H6: =SUM($G$2:G6) -> 69211748 | I6: =((H6/2.5)/48)/10000 -> 57.676457 | J6: =I6+F6+E6 -> 77.942873 | K6: =A6*J6 -> 389.71436
A7: 6 | B7: 7607392 | C7: 6392608 | D7: =C7/2.5 -> 2557043.2 | E7: =(D7/60)/10000 -> 4.2617387 | F7: =(B7*2)/1000000 -> 15.214784 | G7: =IFERROR(B7+C7,0) -> 14000000 | H7: =SUM($G$2:G7) -> 83211748 | I7: =((H7/2.5)/48)/10000 -> 69.343123 | J7: =I7+F7+E7 -> 88.819646 | K7: =A7*J7 -> 532.91788
A8: 7 | B8: 7667395 | C8: 6332605 | D8: =C8/2.5 -> 2533042 | E8: =(D8/60)/10000 -> 4.2217367 | F8: =(B8*2)/1000000 -> 15.33479 | G8: =IFERROR(B8+C8,0) -> 14000000 | H8: =SUM($G$2:G8) -> 97211748 | I8: =((H8/2.5)/48)/10000 -> 81.00979 | J8: =I8+F8+E8 -> 100.56632 | K8: =A8*J8 -> 703.96422
A9: 8 | B9: 8500000 | C9: 5395263 | D9: =C9/2.5 -> 2158105.2 | E9: =(D9/60)/10000 -> 3.596842 | F9: =(B9*2)/1000000 -> 17 | G9: =IFERROR(B9+C9,0) -> 13895263 | H9: =SUM($G$2:G9) -> 111107011 | I9: =((H9/2.5)/48)/10000 -> 92.589176 | J9: =I9+F9+E9 -> 113.18602 | K9: =A9*J9 -> 905.48814
A10: 9 | B10: 8500000 | C10: 4363122 | D10: =C10/2.5 -> 1745248.8 | E10: =(D10/60)/10000 -> 2.908748 | F10: =(B10*2)/1000000 -> 17 | G10: =IFERROR(B10+C10,0) -> 12863122 | H10: =SUM($G$2:G10) -> 123970133 | I10: =((H10/2.5)/48)/10000 -> 103.30844 | J10: =I10+F10+E10 -> 123.21719 | K10: =A10*J10 -> 1108.9547
A11: 10 | B11: 8500000 | C11: 4442005 | D11: =C11/2.5 -> 1776802 | E11: =(D11/60)/10000 -> 2.9613367 | F11: =(B11*2)/1000000 -> 17 | G11: =IFERROR(B11+C11,0) -> 12942005 | H11: =SUM($G$2:G11) -> 136912138 | I11: =((H11/2.5)/48)/10000 -> 114.09345 | J11: =I11+F11+E11 -> 134.05479 | K11: =A11*J11 -> 1340.5479
A12: 11 | B12: 8500000 | C12: 4314333 | D12: =C12/2.5 -> 1725733.2 | E12: =(D12/60)/10000 -> 2.876222 | F12: =(B12*2)/1000000 -> 17 | G12: =IFERROR(B12+C12,0) -> 12814333 | H12: =SUM($G$2:G12) -> 149726471 | I12: =((H12/2.5)/48)/10000 -> 124.77206 | J12: =I12+F12+E12 -> 144.64828 | K12: =A12*J12 -> 1591.1311
A13: 12 | B13: 8500000 | C13: 4195986 | D13: =C13/2.5 -> 1678394.4 | E13: =(D13/60)/10000 -> 2.797324 | F13: =(B13*2)/1000000 -> 17 | G13: =IFERROR(B13+C13,0) -> 12695986 | H13: =SUM($G$2:G13) -> 162422457 | I13: =((H13/2.5)/48)/10000 -> 135.35205 | J13: =I13+F13+E13 -> 155.14937 | K13: =A13*J13 -> 1861.7925
... A34: 33 | B34: 5409319 | C34: 8512356 | D34: =C34/2.5 -> 3404942.4 | E34: =(D34/60)/10000 -> 5.674904 | F34: =(B34*2)/1000000 -> 10.818638 | G34: =IFERROR(B34+C34,0) -> 13921675 | H34: =SUM($G$2:G34) -> 455615999 | I34: =((H34/2.5)/48)/10000 -> 379.68 | J34: =I34+F34+E34 -> 396.17354 | K34: =A34*J34 -> 13073.727
C35: =SUM(C2:C33) -> 230612124
H37: Key Outputs | I37: Total Land Occupation (ha·year) | J37: =MAX(K2:K33) -> 12252.601
I38: Max Total Area Used (ha) | J38: =MAX(J2:J33) -> 382.89378
G44: Parameters | H44: Units | I44: Value
G45: Haul Road Width | H45: m | I45: 26
G46: Haul Road Gradient | H46: % | I46: 10
G47: Mining Bench Height | H47: m | I47: 10
G48: Safety Berm Width | H48: m | I48: 8
G49: Batter Angle | H49: degrees | I49: 60
G50: Projection Angle | H50: degrees | I50: 18.5
G51: Density | I51: 2.5
G52: Level Height | H52: m | I52: 10
G53: Average dump hieght | H53: m | I53: 60
G54: K_leach | H54: ha per Mt ore | I54: 2
G55: avg. pit depth | H55: m | I55: 48
A58: 1 | B58: 8500000 | C58: 5449307 | D58: 0.64 | E58: 2.3949 | F58: 732712048 | G58: 666101861
A59: 2 | B59: 8500000 | C59: 5039809 | D59: 0.59 | E59: 1.7252 | F59: 470620428 | G59: 388942502
A60: 3 | B60: 8500000 | C60: 5222632 | D60: 0.61 | E60: 1.8683 | F60: 526309279 | G60: 395423952
A61: 4 | B61: 8316331 | C61: 5683669 | D61: 0.68 | E61: 2.2595 | F61: 663624421 | G61: 453264409
A62: 5 | B62: 8199812 | C62: 5800188 | D62: 0.71 | E62: 2.4709 | F62: 733896406 | G62: 455691927
A63: 6 | B63: 7607392 | C63: 6392608 | D63: 0.84 | E63: 2.4595 | F63: 673560007 | G63: 380207064
A64: 7 | B64: 7667395 | C64: 6332605 | D64: 0.83 | E64: 2.433 | F64: 669802147 | G64: 343714409
A65: 8 | B65: 8500000 | C65: 5395263 | D65: 0.63 | E65: 2.4608 | F65: 758836774 | G65: 354002955
A66: 9 | B66: 8500000 | C66: 4363122 | D66: 0.51 | E66: 2.3449 | F66: 716614374 | G66: 303914449
A67: 10 | B67: 8500000 | C67: 4442005 | D67: 0.52 | E67: 2.3413 | F67: 714920052 | G67: 275632628
A68: 11 | B68: 8500000 | C68: 4314333 | D68: 0.51 | E68: 2.3536 | F68: 720212032 | G68: 252429924
...

Sheet Schedule_3
A1: Year | B1: Ore (t) | C1: Waste (t) | D1: Waste (m^3) | E1: Dumps Area (ha) | F1: Leach Facility Area (ha) | G1: Total Material Mined (t) | H1: Cumulative Material (t) | I1: Estimated pit area (ha) | J1: Disturbed Area (ha) | K1: Land Occupation (ha·year)
A2: 1 | B2: 9000000 | C2: 5719151 | D2: =C2/2.5 -> 2287660.4 | E2: =(D2/60)/10000 -> 3.8127673 | F2: =(B2*2)/1000000 -> 18 | G2: =IFERROR(B2+C2,0) -> 14719151 | H2: =SUM($G$2:G2) -> 14719151 | I2: =((H2/2.5)/48)/10000 -> 12.265959 | J2: =I2+F2+E2 -> 34.078727 | K2: =A2*J2 -> 34.078727
A3: 2 | B3: 9000000 | C3: 5347899 | D3: =C3/2.5 -> 2139159.6 | E3: =(D3/60)/10000 -> 3.565266 | F3: =(B3*2)/1000000 -> 18 | G3: =IFERROR(B3+C3,0) -> 14347899 | H3: =SUM($G$2:G3) -> 29067050 | I3: =((H3/2.5)/48)/10000 -> 24.222542 | J3: =I3+F3+E3 -> 45.787808 | K3: =A3*J3 -> 91.575615
A4: 3 | B4: 9000000 | C4: 5597773 | D4: =C4/2.5 -> 2239109.2 | E4: =(D4/60)/10000 -> 3.7318487 | F4: =(B4*2)/1000000 -> 18 | G4: =IFERROR(B4+C4,0) -> 14597773 | H4: =SUM($G$2:G4) -> 43664823 | I4: =((H4/2.5)/48)/10000 -> 36.387352 | J4: =I4+F4+E4 -> 58.119201 | K4: =A4*J4 -> 174.3576
A5: 4 | B5: 8893563 | C5: 6106437 | D5: =C5/2.5 -> 2442574.8 | E5: =(D5/60)/10000 -> 4.070958 | F5: =(B5*2)/1000000 -> 17.787126 | G5: =IFERROR(B5+C5,0) -> 15000000 | H5: =SUM($G$2:G5) -> 58664823 | I5: =((H5/2.5)/48)/10000 -> 48.887352 | J5: =I5+F5+E5 -> 70.745436 | K5: =A5*J5 -> 282.98175
A6: 5 | B6: 8593855 | C6: 6406145 | D6: =C6/2.5 -> 2562458 | E6: =(D6/60)/10000 -> 4.2707633 | F6: =(B6*2)/1000000 -> 17.18771 | G6: =IFERROR(B6+C6,0) -> 15000000 | H6: =SUM($G$2:G6) -> 73664823 | I6: =((H6/2.5)/48)/10000 -> 61.387353 | J6: =I6+F6+E6 -> 82.845826 | K6: =A6*J6 -> 414.22913
A7: 6 | B7: 8016112 | C7: 6983888 | D7: =C7/2.5 -> 2793555.2 | E7: =(D7/60)/10000 -> 4.6559253 | F7: =(B7*2)/1000000 -> 16.032224 | G7: =IFERROR(B7+C7,0) -> 15000000 | H7: =SUM($G$2:G7) -> 88664823 | I7: =((H7/2.5)/48)/10000 -> 73.887353 | J7: =I7+F7+E7 -> 94.575502 | K7: =A7*J7 -> 567.45301
A8: 7 | B8: 8626053 | C8: 6373947 | D8: =C8/2.5 -> 2549578.8 | E8: =(D8/60)/10000 -> 4.249298 | F8: =(B8*2)/1000000 -> 17.252106 | G8: =IFERROR(B8+C8,0) -> 15000000 | H8: =SUM($G$2:G8) -> 103664823 | I8: =((H8/2.5)/48)/10000 -> 86.387353 | J8: =I8+F8+E8 -> 107.88876 | K8: =A8*J8 -> 755.2213
A9: 8 | B9: 9000000 | C9: 5083947 | D9: =C9/2.5 -> 2033578.8 | E9: =(D9/60)/10000 -> 3.389298 | F9: =(B9*2)/1000000 -> 18 | G9: =IFERROR(B9+C9,0) -> 14083947 | H9: =SUM($G$2:G9) -> 117748770 | I9: =((H9/2.5)/48)/10000 -> 98.123975 | J9: =I9+F9+E9 -> 119.51327 | K9: =A9*J9 -> 956.10618
A10: 9 | B10: 9000000 | C10: 4683439 | D10: =C10/2.5 -> 1873375.6 | E10: =(D10/60)/10000 -> 3.1222927 | F10: =(B10*2)/1000000 -> 18 | G10: =IFERROR(B10+C10,0) -> 13683439 | H10: =SUM($G$2:G10) -> 131432209 | I10: =((H10/2.5)/48)/10000 -> 109.52684 | J10: =I10+F10+E10 -> 130.64913 | K10: =A10*J10 -> 1175.8422
A11: 10 | B11: 9000000 | C11: 4649437 | D11: =C11/2.5 -> 1859774.8 | E11: =(D11/60)/10000 -> 3.0996247 | F11: =(B11*2)/1000000 -> 18 | G11: =IFERROR(B11+C11,0) -> 13649437 | H11: =SUM($G$2:G11) -> 145081646 | I11: =((H11/2.5)/48)/10000 -> 120.90137 | J11: =I11+F11+E11 -> 142.001 | K11: =A11*J11 -> 1420.01
A12: 11 | B12: 9000000 | C12: 5945119 | D12: =C12/2.5 -> 2378047.6 | E12: =(D12/60)/10000 -> 3.9634127 | F12: =(B12*2)/1000000 -> 18 | G12: =IFERROR(B12+C12,0) -> 14945119 | H12: =SUM($G$2:G12) -> 160026765 | I12: =((H12/2.5)/48)/10000 -> 133.35564 | J12: =I12+F12+E12 -> 155.31905 | K12: =A12*J12 -> 1708.5096
A13: 12 | B13: 9000000 | C13: 4461373 | D13: =C13/2.5 -> 1784549.2 | E13: =(D13/60)/10000 -> 2.9742487 | F13: =(B13*2)/1000000 -> 18 | G13: =IFERROR(B13+C13,0) -> 13461373 | H13: =SUM($G$2:G13) -> 173488138 | I13: =((H13/2.5)/48)/10000 -> 144.57345 | J13: =I13+F13+E13 -> 165.5477 | K13: =A13*J13 -> 1986.5724
... A33: 32 | B33: 5409941 | C33: 8454163 | D33: =C33/2.5 -> 3381665.2 | E33: =(D33/60)/10000 -> 5.6361087 | F33: =(B33*2)/1000000 -> 10.819882 | G33: =IFERROR(B33+C33,0) -> 13864104 | H33: =SUM($G$2:G33) -> 470673921 | I33: =((H33/2.5)/48)/10000 -> 392.22827 | J33: =I33+F33+E33 -> 408.68426 | K33: =A33*J33 -> 13077.896
C35: =SUM(C2:C33) -> 251328003
H37: Key Outputs | I37: Total Land Occupation (ha·year) | J37: =MAX(K2:K33) -> 13077.896
I38: Max Total Area Used (ha) | J38: =MAX(J2:J33) -> 408.68426
G44: Parameters | H44: Units | I44: Value
G45: Haul Road Width | H45: m | I45: 26
G46: Haul Road Gradient | H46: % | I46: 10
G47: Mining Bench Height | H47: m | I47: 10
G48: Safety Berm Width | H48: m | I48: 8
G49: Batter Angle | H49: degrees | I49: 60
G50: Projection Angle | H50: degrees | I50: 18.5
G51: Density | I51: 2.5
G52: Level Height | H52: m | I52: 10
G53: Average dump hieght | H53: m | I53: 60
G54: K_leach | H54: ha per Mt ore | I54: 2
G55: avg. pit depth | H55: m | I55: 48
A59: 1 | B59: 9000000 | C59: 5719151 | D59: 0.64 | E59: 2.3639 | F59: 763066546 | G59: 693696860
A60: 2 | B60: 9000000 | C60: 5347899 | D60: 0.59 | E60: 1.7216 | F60: 496781606 | G60: 410563311
A61: 3 | B61: 9000000 | C61: 5597773 | D61: 0.62 | E61: 1.9143 | F61: 576211234 | G61: 432916029
A62: 4 | B62: 8893563 | C62: 6106437 | D62: 0.69 | E62: 2.3382 | F62: 741997899 | G62: 506794549
A63: 5 | B63: 8593855 | C63: 6406145 | D63: 0.75 | E63: 2.4738 | F63: 769255785 | G63: 477647320
A64: 6 | B64: 8016112 | C64: 6983888 | D64: 0.87 | E64: 2.4348 | F64: 699774062 | G64: 395004215
A65: 7 | B65: 8626053 | C65: 6373947 | D65: 0.74 | E65: 2.4702 | F65: 770893673 | G65: 395590346
A66: 8 | B66: 9000000 | C66: 5083947 | D66: 0.56 | E66: 2.3919 | F66: 776829870 | G66: 362396867
A67: 9 | B67: 9000000 | C67: 4683439 | D67: 0.52 | E67: 2.3439 | F67: 758146505 | G67: 321528127
A68: 10 | B68: 9000000 | C68: 4649437 | D68: 0.52 | E68: 2.3486 | F68: 760209005 | G68: 293093480
A69: 11 | B69: 9000000 | C69: 5945119 | D69: 0.66 | E69: 2.3758 | F69: 767292440 | G69: 268931319
...

Sheet Schedule_4
A1: Year | B1: Ore (t) | C1: Waste (t) | D1: Waste (m^3) | E1: Dumps Area (ha) | F1: Leach Facility Area (ha) | G1: Total Material Mined (t) | H1: Cumulative Material (t) | I1: Estimated pit area (ha) | J1: Disturbed Area (ha) | K1: Land Occupation (ha·year)
A2: 1 | B2: 9600000 | C2: 5597858 | D2: =C2/2.5 -> 2239143.2 | E2: =(D2/60)/10000 -> 3.7319053 | F2: =(B2*2)/1000000 -> 19.2 | G2: =IFERROR(B2+C2,0) -> 15197858 | H2: =SUM($G$2:G2) -> 15197858 | I2: =((H2/2.5)/48)/10000 -> 12.664882 | J2: =I2+F2+E2 -> 35.596787 | K2: =A2*J2 -> 35.596787
A3: 2 | B3: 9600000 | C3: 5720945 | D3: =C3/2.5 -> 2288378 | E3: =(D3/60)/10000 -> 3.8139633 | F3: =(B3*2)/1000000 -> 19.2 | G3: =IFERROR(B3+C3,0) -> 15320945 | H3: =SUM($G$2:G3) -> 30518803 | I3: =((H3/2.5)/48)/10000 -> 25.432336 | J3: =I3+F3+E3 -> 48.446299 | K3: =A3*J3 -> 96.892598
A4: 3 | B4: 9600000 | C4: 6234335 | D4: =C4/2.5 -> 2493734 | E4: =(D4/60)/10000 -> 4.1562233 | F4: =(B4*2)/1000000 -> 19.2 | G4: =IFERROR(B4+C4,0) -> 15834335 | H4: =SUM($G$2:G4) -> 46353138 | I4: =((H4/2.5)/48)/10000 -> 38.627615 | J4: =I4+F4+E4 -> 61.983838 | K4: =A4*J4 -> 185.95151
A5: 4 | B5: 9463269 | C5: 6536731 | D5: =C5/2.5 -> 2614692.4 | E5: =(D5/60)/10000 -> 4.3578207 | F5: =(B5*2)/1000000 -> 18.926538 | G5: =IFERROR(B5+C5,0) -> 16000000 | H5: =SUM($G$2:G5) -> 62353138 | I5: =((H5/2.5)/48)/10000 -> 51.960948 | J5: =I5+F5+E5 -> 75.245307 | K5: =A5*J5 -> 300.98123
A6: 5 | B6: 8770456 | C6: 7229544 | D6: =C6/2.5 -> 2891817.6 | E6: =(D6/60)/10000 -> 4.819696 | F6: =(B6*2)/1000000 -> 17.540912 | G6: =IFERROR(B6+C6,0) -> 16000000 | H6: =SUM($G$2:G6) -> 78353138 | I6: =((H6/2.5)/48)/10000 -> 65.294282 | J6: =I6+F6+E6 -> 87.65489 | K6: =A6*J6 -> 438.27445
A7: 6 | B7: 8719479 | C7: 7280522 | D7: =C7/2.5 -> 2912208.8 | E7: =(D7/60)/10000 -> 4.8536813 | F7: =(B7*2)/1000000 -> 17.438958 | G7: =IFERROR(B7+C7,0) -> 16000001 | H7: =SUM($G$2:G7) -> 94353139 | I7: =((H7/2.5)/48)/10000 -> 78.627616 | J7: =I7+F7+E7 -> 100.92026 | K7: =A7*J7 -> 605.52153
A8: 7 | B8: 9600000 | C8: 5844697 | D8: =C8/2.5 -> 2337878.8 | E8: =(D8/60)/10000 -> 3.8964647 | F8: =(B8*2)/1000000 -> 19.2 | G8: =IFERROR(B8+C8,0) -> 15444697 | H8: =SUM($G$2:G8) -> 109797836 | I8: =((H8/2.5)/48)/10000 -> 91.498197 | J8: =I8+F8+E8 -> 114.59466 | K8: =A8*J8 -> 802.16263
A9: 8 | B9: 9600000 | C9: 4888526 | D9: =C9/2.5 -> 1955410.4 | E9: =(D9/60)/10000 -> 3.2590173 | F9: =(B9*2)/1000000 -> 19.2 | G9: =IFERROR(B9+C9,0) -> 14488526 | H9: =SUM($G$2:G9) -> 124286362 | I9: =((H9/2.5)/48)/10000 -> 103.57197 | J9: =I9+F9+E9 -> 126.03099 | K9: =A9*J9 -> 1008.2479
A10: 9 | B10: 9600000 | C10: 4855304 | D10: =C10/2.5 -> 1942121.6 | E10: =(D10/60)/10000 -> 3.2368693 | F10: =(B10*2)/1000000 -> 19.2 | G10: =IFERROR(B10+C10,0) -> 14455304 | H10: =SUM($G$2:G10) -> 138741666 | I10: =((H10/2.5)/48)/10000 -> 115.61805 | J10: =I10+F10+E10 -> 138.05492 | K10: =A10*J10 -> 1242.4943
A11: 10 | B11: 9600000 | C11: 4676234 | D11: =C11/2.5 -> 1870493.6 | E11: =(D11/60)/10000 -> 3.1174893 | F11: =(B11*2)/1000000 -> 19.2 | G11: =IFERROR(B11+C11,0) -> 14276234 | H11: =SUM($G$2:G11) -> 153017900 | I11: =((H11/2.5)/48)/10000 -> 127.51492 | J11: =I11+F11+E11 -> 149.83241 | K11: =A11*J11 -> 1498.3241
A12: 11 | B12: 9600000 | C12: 6254607 | D12: =C12/2.5 -> 2501842.8 | E12: =(D12/60)/10000 -> 4.169738 | F12: =(B12*2)/1000000 -> 19.2 | G12: =IFERROR(B12+C12,0) -> 15854607 | H12: =SUM($G$2:G12) -> 168872507 | I12: =((H12/2.5)/48)/10000 -> 140.72709 | J12: =I12+F12+E12 -> 164.09683 | K12: =A12*J12 -> 1805.0651
A13: 12 | B13: 9600000 | C13: 6380704 | D13: =C13/2.5 -> 2552281.6 | E13: =(D13/60)/10000 -> 4.2538027 | F13: =(B13*2)/1000000 -> 19.2 | G13: =IFERROR(B13+C13,0) -> 15980704 | H13: =SUM($G$2:G13) -> 184853211 | I13: =((H13/2.5)/48)/10000 -> 154.04434 | J13: =I13+F13+E13 -> 177.49815 | K13: =A13*J13 -> 2129.9777
... A30: 29 | B30: 3678910 | C30: 5385545 | D30: =C30/2.5 -> 2154218 | E30: =(D30/60)/10000 -> 3.5903633 | F30: =(B30*2)/1000000 -> 7.35782 | G30: =IFERROR(B30+C30,0) -> 9064455 | H30: =SUM($G$2:G30) -> 449914881 | I30: =((H30/2.5)/48)/10000 -> 374.92907 | J30: =I30+F30+E30 -> 385.87725 | K30: =A30*J30 -> 11190.44
C35: =SUM(C2:C33) -> 234923521
H37: Key Outputs | I37: Total Land Occupation (ha·year) | J37: =MAX(K2:K33) -> 11190.44
I38: Max Total Area Used (ha) | J38: =MAX(J2:J33) -> 386.02354
G44: Parameters | H44: Units | I44: Value
G45: Haul Road Width | H45: m | I45: 26
G46: Haul Road Gradient | H46: % | I46: 10
G47: Mining Bench Height | H47: m | I47: 10
G48: Safety Berm Width | H48: m | I48: 8
G49: Batter Angle | H49: degrees | I49: 60
G50: Projection Angle | H50: degrees | I50: 18.5
G51: Density | I51: 2.5
G52: Level Height | H52: m | I52: 10
G53: Average dump hieght | H53: m | I53: 60
G54: K_leach | H54: ha per Mt ore | I54: 2
G55: avg. pit depth | H55: m | I55: 48
A60: 1 | B60: 9600000 | C60: 5597858 | D60: 0.58 | E60: 2.3401 | F60: 805038998 | G60: 731853635
A61: 2 | B61: 9600000 | C61: 5720945 | D61: 0.6 | E61: 1.7267 | F61: 532091770 | G61: 439745264
A62: 3 | B62: 9600000 | C62: 6234335 | D62: 0.65 | E62: 2.0628 | F62: 679732668 | G62: 510693214
A63: 4 | B63: 9463269 | C63: 6536731 | D63: 0.69 | E63: 2.4485 | F63: 837695114 | G63: 572157035
A64: 5 | B64: 8770456 | C64: 7229544 | D64: 0.82 | E64: 2.5245 | F64: 803359628 | G64: 498823123
A65: 6 | B65: 8719479 | C65: 7280522 | D65: 0.83 | E65: 2.4617 | F65: 773039295 | G65: 436360529
A66: 7 | B66: 9600000 | C66: 5844697 | D66: 0.61 | E66: 2.4619 | F66: 858334421 | G66: 440461276
A67: 8 | B67: 9600000 | C67: 4888526 | D67: 0.51 | E67: 2.359 | F67: 815758568 | G67: 380557392
A68: 9 | B68: 9600000 | C68: 4855304 | D68: 0.51 | E68: 2.3572 | F68: 815042927 | G68: 345657764
A69: 10 | B69: 9600000 | C69: 4676234 | D69: 0.49 | E69: 2.3973 | F69: 833471461 | G69: 321339329
A70: 11 | B70: 9600000 | C70: 6254607 | D70: 0.65 | E70: 2.4739 | F70: 862319578 | G70: 302237751
...

Sheet Schedule_5
A1: Year | B1: Ore (t) | C1: Waste (t) | D1: Waste (m^3) | E1: Dumps Area (ha) | F1: Leach Facility Area (ha) | G1: Total Material Mined (t) | H1: Cumulative Material (t) | I1: Estimated pit area (ha) | J1: Disturbed Area (ha) | K1: Land Occupation (ha·year)
A2: 1 | B2: 10000000 | C2: 5918017 | D2: =C2/2.5 -> 2367206.8 | E2: =(D2/60)/10000 -> 3.9453447 | F2: =(B2*2)/1000000 -> 20 | G2: =IFERROR(B2+C2,0) -> 15918017 | H2: =SUM($G$2:G2) -> 15918017 | I2: =((H2/2.5)/48)/10000 -> 13.265014 | J2: =I2+F2+E2 -> 37.210359 | K2: =A2*J2 -> 37.210359
A3: 2 | B3: 10000000 | C3: 5925319 | D3: =C3/2.5 -> 2370127.6 | E3: =(D3/60)/10000 -> 3.9502127 | F3: =(B3*2)/1000000 -> 20 | G3: =IFERROR(B3+C3,0) -> 15925319 | H3: =SUM($G$2:G3) -> 31843336 | I3: =((H3/2.5)/48)/10000 -> 26.536113 | J3: =I3+F3+E3 -> 50.486326 | K3: =A3*J3 -> 100.97265
A4: 3 | B4: 10000000 | C4: 6539740 | D4: =C4/2.5 -> 2615896 | E4: =(D4/60)/10000 -> 4.3598267 | F4: =(B4*2)/1000000 -> 20 | G4: =IFERROR(B4+C4,0) -> 16539740 | H4: =SUM($G$2:G4) -> 48383076 | I4: =((H4/2.5)/48)/10000 -> 40.31923 | J4: =I4+F4+E4 -> 64.679057 | K4: =A4*J4 -> 194.03717
A5: 4 | B5: 10000000 | C5: 6921927 | D5: =C5/2.5 -> 2768770.8 | E5: =(D5/60)/10000 -> 4.614618 | F5: =(B5*2)/1000000 -> 20 | G5: =IFERROR(B5+C5,0) -> 16921927 | H5: =SUM($G$2:G5) -> 65305003 | I5: =((H5/2.5)/48)/10000 -> 54.420836 | J5: =I5+F5+E5 -> 79.035454 | K5: =A5*J5 -> 316.14182
A6: 5 | B6: 9207125 | C6: 7792875 | D6: =C6/2.5 -> 3117150 | E6: =(D6/60)/10000 -> 5.19525 | F6: =(B6*2)/1000000 -> 18.41425 | G6: =IFERROR(B6+C6,0) -> 17000000 | H6: =SUM($G$2:G6) -> 82305003 | I6: =((H6/2.5)/48)/10000 -> 68.587502 | J6: =I6+F6+E6 -> 92.197002 | K6: =A6*J6 -> 460.98501
A7: 6 | B7: 9630040 | C7: 7369960 | D7: =C7/2.5 -> 2947984 | E7: =(D7/60)/10000 -> 4.9133067 | F7: =(B7*2)/1000000 -> 19.26008 | G7: =IFERROR(B7+C7,0) -> 17000000 | H7: =SUM($G$2:G7) -> 99305003 | I7: =((H7/2.5)/48)/10000 -> 82.754169 | J7: =I7+F7+E7 -> 106.92756 | K7: =A7*J7 -> 641.56534
A8: 7 | B8: 10000000 | C8: 5552884 | D8: =C8/2.5 -> 2221153.6 | E8: =(D8/60)/10000 -> 3.7019227 | F8: =(B8*2)/1000000 -> 20 | G8: =IFERROR(B8+C8,0) -> 15552884 | H8: =SUM($G$2:G8) -> 114857887 | I8: =((H8/2.5)/48)/10000 -> 95.714906 | J8: =I8+F8+E8 -> 119.41683 | K8: =A8*J8 -> 835.9178
A9: 8 | B9: 10000000 | C9: 5024070 | D9: =C9/2.5 -> 2009628 | E9: =(D9/60)/10000 -> 3.34938 | F9: =(B9*2)/1000000 -> 20 | G9: =IFERROR(B9+C9,0) -> 15024070 | H9: =SUM($G$2:G9) -> 129881957 | I9: =((H9/2.5)/48)/10000 -> 108.23496 | J9: =I9+F9+E9 -> 131.58434 | K9: =A9*J9 -> 1052.6748
A10: 9 | B10: 10000000 | C10: 4890964 | D10: =C10/2.5 -> 1956385.6 | E10: =(D10/60)/10000 -> 3.2606427 | F10: =(B10*2)/1000000 -> 20 | G10: =IFERROR(B10+C10,0) -> 14890964 | H10: =SUM($G$2:G10) -> 144772921 | I10: =((H10/2.5)/48)/10000 -> 120.6441 | J10: =I10+F10+E10 -> 143.90474 | K10: =A10*J10 -> 1295.1427
A11: 10 | B11: 10000000 | C11: 6102950 | D11: =C11/2.5 -> 2441180 | E11: =(D11/60)/10000 -> 4.0686333 | F11: =(B11*2)/1000000 -> 20 | G11: =IFERROR(B11+C11,0) -> 16102950 | H11: =SUM($G$2:G11) -> 160875871 | I11: =((H11/2.5)/48)/10000 -> 134.06323 | J11: =I11+F11+E11 -> 158.13186 | K11: =A11*J11 -> 1581.3186
A12: 11 | B12: 10000000 | C12: 4663374 | D12: =C12/2.5 -> 1865349.6 | E12: =(D12/60)/10000 -> 3.108916 | F12: =(B12*2)/1000000 -> 20 | G12: =IFERROR(B12+C12,0) -> 14663374 | H12: =SUM($G$2:G12) -> 175539245 | I12: =((H12/2.5)/48)/10000 -> 146.2827 | J12: =I12+F12+E12 -> 169.39162 | K12: =A12*J12 -> 1863.3078
A13: 12 | B13: 10000000 | C13: 6907308 | D13: =C13/2.5 -> 2762923.2 | E13: =(D13/60)/10000 -> 4.604872 | F13: =(B13*2)/1000000 -> 20 | G13: =IFERROR(B13+C13,0) -> 16907308 | H13: =SUM($G$2:G13) -> 192446553 | I13: =((H13/2.5)/48)/10000 -> 160.37213 | J13: =I13+F13+E13 -> 184.977 | K13: =A13*J13 -> 2219.724
... A26: 25 | B26: 5187192 | C26: 7820335 | D26: =C26/2.5 -> 3128134 | E26: =(D26/60)/10000 -> 5.2135567 | F26: =(B26*2)/1000000 -> 10.374384 | G26: =IFERROR(B26+C26,0) -> 13007527 | H26: =SUM($G$2:G26) -> 409454080 | I26: =((H26/2.5)/48)/10000 -> 341.21173 | J26: =I26+F26+E26 -> 356.79967 | K26: =A26*J26 -> 8919.9919
C35: =SUM(C2:C33) -> 207585281
H37: Key Outputs | I37: Total Land Occupation (ha·year) | J37: =MAX(K2:K33) -> 8919.9919
I38: Max Total Area Used (ha) | J38: =MAX(J2:J33) -> 356.79967
G44: Parameters | H44: Units | I44: Value
G45: Haul Road Width | H45: m | I45: 26
G46: Haul Road Gradient | H46: % | I46: 10
G47: Mining Bench Height | H47: m | I47: 10
G48: Safety Berm Width | H48: m | I48: 8
G49: Batter Angle | H49: degrees | I49: 60
G50: Projection Angle | H50: degrees | I50: 18.5
G51: Density | I51: 2.5
G52: Level Height | H52: m | I52: 10
G53: Average dump hieght | H53: m | I53: 60
G54: K_leach | H54: ha per Mt ore | I54: 2
G55: avg. pit depth | H55: m | I55: 48
A60: 1 | B60: 10000000 | C60: 5918017 | D60: 0.59 | E60: 2.3138 | F60: 826114543 | G60: 751013221
A61: 2 | B61: 10000000 | C61: 5925319 | D61: 0.59 | E61: 1.7237 | F61: 552996801 | G61: 457022149
A62: 3 | B62: 10000000 | C62: 6539740 | D62: 0.65 | E62: 2.1175 | F62: 733213079 | G62: 550873839
A63: 4 | B63: 10000000 | C63: 6921927 | D63: 0.69 | E63: 2.466 | F63: 893269960 | G63: 610115402
A64: 5 | B64: 9207125 | C64: 7792875 | D64: 0.85 | E64: 2.4994 | F64: 831988183 | G64: 516599203
A65: 6 | B65: 9630040 | C65: 7369960 | D65: 0.77 | E65: 2.477 | F65: 862791441 | G65: 487023275
A66: 7 | B66: 10000000 | C66: 5552884 | D66: 0.56 | E66: 2.4079 | F66: 870870866 | G66: 446894455
A67: 8 | B67: 10000000 | C67: 5024070 | D67: 0.5 | E67: 2.3497 | F67: 845657945 | G67: 394505673
A68: 9 | B68: 10000000 | C68: 4890964 | D68: 0.49 | E68: 2.3587 | F68: 850257028 | G68: 360591981
A69: 10 | B69: 10000000 | C69: 6102950 | D69: 0.61 | E69: 2.4257 | F69: 877277584 | G69: 338228486
A70: 11 | B70: 10000000 | C70: 4663374 | D70: 0.47 | E70: 2.5246 | F70: 927765215 | G70: 325176048
...

Sheet Schedule_6
A1: Year | B1: Ore (t) | C1: Waste (t) | D1: Waste (m^3) | E1: Dumps Area (ha) | F1: Leach Facility Area (ha) | G1: Total Material Mined (t) | H1: Cumulative Material (t) | I1: Estimated pit area (ha) | J1: Disturbed Area (ha) | K1: Land Occupation (ha·year)
A2: 1 | B2: 9000000 | C2: 5281971 | D2: =C2/2.5 -> 2112788.4 | E2: =(D2/60)/10000 -> 3.521314 | F2: =(B2*2)/1000000 -> 18 | G2: =IFERROR(B2+C2,0) -> 14281971 | H2: =SUM($G$2:G2) -> 14281971 | I2: =((H2/2.5)/48)/10000 -> 11.901642 | J2: =I2+F2+E2 -> 33.422956 | K2: =A2*J2 -> 33.422956
A3: 2 | B3: 9000000 | C3: 5348460 | D3: =C3/2.5 -> 2139384 | E3: =(D3/60)/10000 -> 3.56564 | F3: =(B3*2)/1000000 -> 18 | G3: =IFERROR(B3+C3,0) -> 14348460 | H3: =SUM($G$2:G3) -> 28630431 | I3: =((H3/2.5)/48)/10000 -> 23.858693 | J3: =I3+F3+E3 -> 45.424333 | K3: =A3*J3 -> 90.848665
A4: 3 | B4: 9000000 | C4: 5642411 | D4: =C4/2.5 -> 2256964.4 | E4: =(D4/60)/10000 -> 3.7616073 | F4: =(B4*2)/1000000 -> 18 | G4: =IFERROR(B4+C4,0) -> 14642411 | H4: =SUM($G$2:G4) -> 43272842 | I4: =((H4/2.5)/48)/10000 -> 36.060702 | J4: =I4+F4+E4 -> 57.822309 | K4: =A4*J4 -> 173.46693
A5: 4 | B5: 9000000 | C5: 6225142 | D5: =C5/2.5 -> 2490056.8 | E5: =(D5/60)/10000 -> 4.1500947 | F5: =(B5*2)/1000000 -> 18 | G5: =IFERROR(B5+C5,0) -> 15225142 | H5: =SUM($G$2:G5) -> 58497984 | I5: =((H5/2.5)/48)/10000 -> 48.74832 | J5: =I5+F5+E5 -> 70.898415 | K5: =A5*J5 -> 283.59366
A6: 5 | B6: 9000000 | C6: 6932538 | D6: =C6/2.5 -> 2773015.2 | E6: =(D6/60)/10000 -> 4.621692 | F6: =(B6*2)/1000000 -> 18 | G6: =IFERROR(B6+C6,0) -> 15932538 | H6: =SUM($G$2:G6) -> 74430522 | I6: =((H6/2.5)/48)/10000 -> 62.025435 | J6: =I6+F6+E6 -> 84.647127 | K6: =A6*J6 -> 423.23563
A7: 6 | B7: 9000000 | C7: 7844416 | D7: =C7/2.5 -> 3137766.4 | E7: =(D7/60)/10000 -> 5.2296107 | F7: =(B7*2)/1000000 -> 18 | G7: =IFERROR(B7+C7,0) -> 16844416 | H7: =SUM($G$2:G7) -> 91274938 | I7: =((H7/2.5)/48)/10000 -> 76.062448 | J7: =I7+F7+E7 -> 99.292059 | K7: =A7*J7 -> 595.75235
A8: 7 | B8: 9000000 | C8: 5777267 | D8: =C8/2.5 -> 2310906.8 | E8: =(D8/60)/10000 -> 3.8515113 | F8: =(B8*2)/1000000 -> 18 | G8: =IFERROR(B8+C8,0) -> 14777267 | H8: =SUM($G$2:G8) -> 106052205 | I8: =((H8/2.5)/48)/10000 -> 88.376837 | J8: =I8+F8+E8 -> 110.22835 | K8: =A8*J8 -> 771.59844
A9: 8 | B9: 9000000 | C9: 4502257 | D9: =C9/2.5 -> 1800902.8 | E9: =(D9/60)/10000 -> 3.0015047 | F9: =(B9*2)/1000000 -> 18 | G9: =IFERROR(B9+C9,0) -> 13502257 | H9: =SUM($G$2:G9) -> 119554462 | I9: =((H9/2.5)/48)/10000 -> 99.628718 | J9: =I9+F9+E9 -> 120.63022 | K9: =A9*J9 -> 965.04178
A10: 9 | B10: 9000000 | C10: 4546727 | D10: =C10/2.5 -> 1818690.8 | E10: =(D10/60)/10000 -> 3.0311513 | F10: =(B10*2)/1000000 -> 18 | G10: =IFERROR(B10+C10,0) -> 13546727 | H10: =SUM($G$2:G10) -> 133101189 | I10: =((H10/2.5)/48)/10000 -> 110.91766 | J10: =I10+F10+E10 -> 131.94881 | K10: =A10*J10 -> 1187.5393
A11: 10 | B11: 9000000 | C11: 4386245 | D11: =C11/2.5 -> 1754498 | E11: =(D11/60)/10000 -> 2.9241633 | F11: =(B11*2)/1000000 -> 18 | G11: =IFERROR(B11+C11,0) -> 13386245 | H11: =SUM($G$2:G11) -> 146487434 | I11: =((H11/2.5)/48)/10000 -> 122.07286 | J11: =I11+F11+E11 -> 142.99702 | K11: =A11*J11 -> 1429.9702
A12: 11 | B12: 9000000 | C12: 4340490 | D12: =C12/2.5 -> 1736196 | E12: =(D12/60)/10000 -> 2.89366 | F12: =(B12*2)/1000000 -> 18 | G12: =IFERROR(B12+C12,0) -> 13340490 | H12: =SUM($G$2:G12) -> 159827924 | I12: =((H12/2.5)/48)/10000 -> 133.18994 | J12: =I12+F12+E12 -> 154.0836 | K12: =A12*J12 -> 1694.9196
A13: 12 | B13: 9000000 | C13: 4238447 | D13: =C13/2.5 -> 1695378.8 | E13: =(D13/60)/10000 -> 2.8256313 | F13: =(B13*2)/1000000 -> 18 | G13: =IFERROR(B13+C13,0) -> 13238447 | H13: =SUM($G$2:G13) -> 173066371 | I13: =((H13/2.5)/48)/10000 -> 144.22198 | J13: =I13+F13+E13 -> 165.04761 | K13: =A13*J13 -> 1980.5713
... A28: 27 | B28: 3743277 | C28: 5523693 | D28: =C28/2.5 -> 2209477.2 | E28: =(D28/60)/10000 -> 3.682462 | F28: =(B28*2)/1000000 -> 7.486554 | G28: =IFERROR(B28+C28,0) -> 9266970 | H28: =SUM($G$2:G28) -> 430609919 | I28: =((H28/2.5)/48)/10000 -> 358.8416 | J28: =I28+F28+E28 -> 370.01062 | K28: =A28*J28 -> 9990.2866
C35: =SUM(C2:C33) -> 222999040
H37: Key Outputs | I37: Total Land Occupation (ha·year) | J37: =MAX(K2:K33) -> 9990.2866
I38: Max Total Area Used (ha) | J38: =MAX(J2:J33) -> 372.03454
G44: Parameters | H44: Units | I44: Value
G45: Haul Road Width | H45: m | I45: 26
G46: Haul Road Gradient | H46: % | I46: 10
G47: Mining Bench Height | H47: m | I47: 10
G48: Safety Berm Width | H48: m | I48: 8
G49: Batter Angle | H49: degrees | I49: 60
G50: Projection Angle | H50: degrees | I50: 18.5
G51: Density | I51: 2.5
G52: Level Height | H52: m | I52: 10
G53: Average dump hieght | H53: m | I53: 60
G54: K_leach | H54: ha per Mt ore | I54: 2
G55: avg. pit depth | H55: m | I55: 48
A57: 1 | B57: 9000000 | C57: 5281971 | D57: 0.59 | E57: 2.3743 | F57: 768841643 | G57: 698946948
A58: 2 | B58: 9000000 | C58: 5348460 | D58: 0.59 | E58: 1.7328 | F58: 501419759 | G58: 414396495
A59: 3 | B59: 9000000 | C59: 5642411 | D59: 0.63 | E59: 1.9704 | F59: 599432085 | G59: 450362198
A60: 4 | B60: 9000000 | C60: 6225142 | D60: 0.69 | E60: 2.4085 | F60: 779981889 | G60: 532738125
A61: 5 | B61: 9000000 | C61: 6932538 | D61: 0.77 | E61: 2.5256 | F61: 826423310 | G61: 513143855
A62: 6 | B62: 9000000 | C62: 7844416 | D62: 0.87 | E62: 2.4519 | F62: 792752066 | G62: 447487874
A63: 7 | B63: 9000000 | C63: 5777267 | D63: 0.64 | E63: 2.4949 | F63: 817451983 | G63: 419482121
A64: 8 | B64: 9000000 | C64: 4502257 | D64: 0.5 | E64: 2.3524 | F64: 762262414 | G64: 355601042
A65: 9 | B65: 9000000 | C65: 4546727 | D65: 0.51 | E65: 2.3511 | F65: 761582199 | G65: 322985197
A66: 10 | B66: 9000000 | C66: 4386245 | D66: 0.49 | E66: 2.3615 | F66: 766456330 | G66: 295502095
A67: 11 | B67: 9000000 | C67: 4340490 | D67: 0.48 | E67: 2.4463 | F67: 801895701 | G67: 281059551
...

Sheet Schedule_7
A1: Year | B1: Ore (t) | C1: Waste (t) | D1: Waste (m^3) | E1: Dumps Area (ha) | F1: Leach Facility Area (ha) | G1: Total Material Mined (t) | H1: Cumulative Material (t) | I1: Estimated pit area (ha) | J1: Disturbed Area (ha) | K1: Land Occupation (ha·year)
A2: 1 | B2: 11400000 | C2: 6747106 | D2: =C2/2.5 -> 2698842.4 | E2: =(D2/60)/10000 -> 4.4980707 | F2: =(B2*2)/1000000 -> 22.8 | G2: =IFERROR(B2+C2,0) -> 18147106 | H2: =SUM($G$2:G2) -> 18147106 | I2: =((H2/2.5)/48)/10000 -> 15.122588 | J2: =I2+F2+E2 -> 42.420659 | K2: =A2*J2 -> 42.420659
A3: 2 | B3: 11400000 | C3: 6910032 | D3: =C3/2.5 -> 2764012.8 | E3: =(D3/60)/10000 -> 4.606688 | F3: =(B3*2)/1000000 -> 22.8 | G3: =IFERROR(B3+C3,0) -> 18310032 | H3: =SUM($G$2:G3) -> 36457138 | I3: =((H3/2.5)/48)/10000 -> 30.380948 | J3: =I3+F3+E3 -> 57.787636 | K3: =A3*J3 -> 115.57527
A4: 3 | B4: 11319271 | C4: 7680729 | D4: =C4/2.5 -> 3072291.6 | E4: =(D4/60)/10000 -> 5.120486 | F4: =(B4*2)/1000000 -> 22.638542 | G4: =IFERROR(B4+C4,0) -> 19000000 | H4: =SUM($G$2:G4) -> 55457138 | I4: =((H4/2.5)/48)/10000 -> 46.214282 | J4: =I4+F4+E4 -> 73.97331 | K4: =A4*J4 -> 221.91993
A5: 4 | B5: 10767982 | C5: 8232018 | D5: =C5/2.5 -> 3292807.2 | E5: =(D5/60)/10000 -> 5.488012 | F5: =(B5*2)/1000000 -> 21.535964 | G5: =IFERROR(B5+C5,0) -> 19000000 | H5: =SUM($G$2:G5) -> 74457138 | I5: =((H5/2.5)/48)/10000 -> 62.047615 | J5: =I5+F5+E5 -> 89.071591 | K5: =A5*J5 -> 356.28636
A6: 5 | B6: 10200518 | C6: 8799482 | D6: =C6/2.5 -> 3519792.8 | E6: =(D6/60)/10000 -> 5.8663213 | F6: =(B6*2)/1000000 -> 20.401036 | G6: =IFERROR(B6+C6,0) -> 19000000 | H6: =SUM($G$2:G6) -> 93457138 | I6: =((H6/2.5)/48)/10000 -> 77.880948 | J6: =I6+F6+E6 -> 104.14831 | K6: =A6*J6 -> 520.74153
A7: 6 | B7: 11400000 | C7: 6967223 | D7: =C7/2.5 -> 2786889.2 | E7: =(D7/60)/10000 -> 4.6448153 | F7: =(B7*2)/1000000 -> 22.8 | G7: =IFERROR(B7+C7,0) -> 18367223 | H7: =SUM($G$2:G7) -> 111824361 | I7: =((H7/2.5)/48)/10000 -> 93.186967 | J7: =I7+F7+E7 -> 120.63178 | K7: =A7*J7 -> 723.7907
A8: 7 | B8: 11400000 | C8: 5884104 | D8: =C8/2.5 -> 2353641.6 | E8: =(D8/60)/10000 -> 3.922736 | F8: =(B8*2)/1000000 -> 22.8 | G8: =IFERROR(B8+C8,0) -> 17284104 | H8: =SUM($G$2:G8) -> 129108465 | I8: =((H8/2.5)/48)/10000 -> 107.59039 | J8: =I8+F8+E8 -> 134.31312 | K8: =A8*J8 -> 940.19186
A9: 8 | B9: 11400000 | C9: 7365120 | D9: =C9/2.5 -> 2946048 | E9: =(D9/60)/10000 -> 4.91008 | F9: =(B9*2)/1000000 -> 22.8 | G9: =IFERROR(B9+C9,0) -> 18765120 | H9: =SUM($G$2:G9) -> 147873585 | I9: =((H9/2.5)/48)/10000 -> 123.22799 | J9: =I9+F9+E9 -> 150.93807 | K9: =A9*J9 -> 1207.5045
A10: 9 | B10: 11400000 | C10: 5543592 | D10: =C10/2.5 -> 2217436.8 | E10: =(D10/60)/10000 -> 3.695728 | F10: =(B10*2)/1000000 -> 22.8 | G10: =IFERROR(B10+C10,0) -> 16943592 | H10: =SUM($G$2:G10) -> 164817177 | I10: =((H10/2.5)/48)/10000 -> 137.34765 | J10: =I10+F10+E10 -> 163.84338 | K10: =A10*J10 -> 1474.5904
A11: 10 | B11: 11399830 | C11: 7600170 | D11: =C11/2.5 -> 3040068 | E11: =(D11/60)/10000 -> 5.06678 | F11: =(B11*2)/1000000 -> 22.79966 | G11: =IFERROR(B11+C11,0) -> 19000000 | H11: =SUM($G$2:G11) -> 183817177 | I11: =((H11/2.5)/48)/10000 -> 153.18098 | J11: =I11+F11+E11 -> 181.04742 | K11: =A11*J11 -> 1810.4742
A12: 11 | B12: 11397240 | C12: 7602760 | D12: =C12/2.5 -> 3041104 | E12: =(D12/60)/10000 -> 5.0685067 | F12: =(B12*2)/1000000 -> 22.79448 | G12: =IFERROR(B12+C12,0) -> 19000000 | H12: =SUM($G$2:G12) -> 202817177 | I12: =((H12/2.5)/48)/10000 -> 169.01431 | J12: =I12+F12+E12 -> 196.8773 | K12: =A12*J12 -> 2165.6503
A13: 12 | B13: 9784883 | C13: 9215117 | D13: =C13/2.5 -> 3686046.8 | E13: =(D13/60)/10000 -> 6.1434113 | F13: =(B13*2)/1000000 -> 19.569766 | G13: =IFERROR(B13+C13,0) -> 19000000 | H13: =SUM($G$2:G13) -> 221817177 | I13: =((H13/2.5)/48)/10000 -> 184.84765 | J13: =I13+F13+E13 -> 210.56082 | K13: =A13*J13 -> 2526.7299
... A27: 26 | B27: 4943998 | C27: 7439465 | D27: =C27/2.5 -> 2975786 | E27: =(D27/60)/10000 -> 4.9596433 | F27: =(B27*2)/1000000 -> 9.887996 | G27: =IFERROR(B27+C27,0) -> 12383463 | H27: =SUM($G$2:G27) -> 481200640 | I27: =((H27/2.5)/48)/10000 -> 401.00053 | J27: =I27+F27+E27 -> 415.84817 | K27: =A27*J27 -> 10812.052
C35: =SUM(C2:C33) -> 259366401
H37: Key Outputs | I37: Total Land Occupation (ha·year) | J37: =MAX(K2:K33) -> 10812.052
I38: Max Total Area Used (ha) | J38: =MAX(J2:J33) -> 415.84817
G44: Parameters | H44: Units | I44: Value
G45: Haul Road Width | H45: m | I45: 26
G46: Haul Road Gradient | H46: % | I46: 10
G47: Mining Bench Height | H47: m | I47: 10
G48: Safety Berm Width | H48: m | I48: 8
G49: Batter Angle | H49: degrees | I49: 60
G50: Projection Angle | H50: degrees | I50: 18.5
G51: Density | I51: 2.5
G52: Level Height | H52: m | I52: 10
G53: Average dump hieght | H53: m | I53: 60
G54: K_leach | H54: ha per Mt ore | I54: 2
G55: avg. pit depth | H55: m | I55: 48
A57: 1 | B57: 11400000 | C57: 6747106 | D57: 0.59 | E57: 2.2464 | F57: 906171926 | G57: 823792660
A58: 2 | B58: 11400000 | C58: 6910032 | D58: 0.61 | E58: 1.7829 | F58: 661125310 | G58: 546384554
A59: 3 | B59: 11319271 | C59: 7680729 | D59: 0.68 | E59: 2.2666 | F59: 907136664 | G59: 681545202
A60: 4 | B60: 10767982 | C60: 8232018 | D60: 0.76 | E60: 2.5307 | F60: 991526018 | G60: 677225612
A61: 5 | B61: 10200518 | C61: 8799482 | D61: 0.86 | E61: 2.467 | F61: 905911422 | G61: 562499719
A62: 6 | B62: 11400000 | C62: 6967223 | D62: 0.61 | E62: 2.4596 | F62: 1017959160 | G62: 574611408
A63: 7 | B63: 11400000 | C63: 5884104 | D63: 0.52 | E63: 2.361 | F63: 969482205 | G63: 497497664
A64: 8 | B64: 11400000 | C64: 7365120 | D64: 0.65 | E64: 2.3568 | F64: 962409713 | G64: 448971234
A65: 9 | B65: 11400000 | C65: 5543592 | D65: 0.49 | E65: 2.4592 | F65: 1022407655 | G65: 433600651
A66: 10 | B66: 11399830 | C66: 7600170 | D66: 0.67 | E66: 2.4912 | F66: 1032555090 | G66: 398094686
A67: 11 | B67: 11397240 | C67: 7602760 | D67: 0.67 | E67: 2.8589 | F67: 1226220993 | G67: 429782977
...

Sheet Schedule_8
A1: Year | B1: Ore (t) | C1: Waste (t) | D1: Waste (m^3) | E1: Dumps Area (ha) | F1: Leach Facility Area (ha) | G1: Total Material Mined (t) | H1: Cumulative Material (t) | I1: Estimated pit area (ha) | J1: Disturbed Area (ha) | K1: Land Occupation (ha·year)
A2: 1 | B2: 9600000 | C2: 5625539 | D2: =C2/2.5 -> 2250215.6 | E2: =(D2/60)/10000 -> 3.7503593 | F2: =(B2*2)/1000000 -> 19.2 | G2: =IFERROR(B2+C2,0) -> 15225539 | H2: =SUM($G$2:G2) -> 15225539 | I2: =((H2/2.5)/48)/10000 -> 12.687949 | J2: =I2+F2+E2 -> 35.638309 | K2: =A2*J2 -> 35.638309
A3: 2 | B3: 9600000 | C3: 5706793 | D3: =C3/2.5 -> 2282717.2 | E3: =(D3/60)/10000 -> 3.8045287 | F3: =(B3*2)/1000000 -> 19.2 | G3: =IFERROR(B3+C3,0) -> 15306793 | H3: =SUM($G$2:G3) -> 30532332 | I3: =((H3/2.5)/48)/10000 -> 25.44361 | J3: =I3+F3+E3 -> 48.448139 | K3: =A3*J3 -> 96.896277
A4: 3 | B4: 9600000 | C4: 6219137 | D4: =C4/2.5 -> 2487654.8 | E4: =(D4/60)/10000 -> 4.1460913 | F4: =(B4*2)/1000000 -> 19.2 | G4: =IFERROR(B4+C4,0) -> 15819137 | H4: =SUM($G$2:G4) -> 46351469 | I4: =((H4/2.5)/48)/10000 -> 38.626224 | J4: =I4+F4+E4 -> 61.972315 | K4: =A4*J4 -> 185.91695
A5: 4 | B5: 9454100 | C5: 6545900 | D5: =C5/2.5 -> 2618360 | E5: =(D5/60)/10000 -> 4.3639333 | F5: =(B5*2)/1000000 -> 18.9082 | G5: =IFERROR(B5+C5,0) -> 16000000 | H5: =SUM($G$2:G5) -> 62351469 | I5: =((H5/2.5)/48)/10000 -> 51.959558 | J5: =I5+F5+E5 -> 75.231691 | K5: =A5*J5 -> 300.92676
A6: 5 | B6: 8800856 | C6: 7199144 | D6: =C6/2.5 -> 2879657.6 | E6: =(D6/60)/10000 -> 4.7994293 | F6: =(B6*2)/1000000 -> 17.601712 | G6: =IFERROR(B6+C6,0) -> 16000000 | H6: =SUM($G$2:G6) -> 78351469 | I6: =((H6/2.5)/48)/10000 -> 65.292891 | J6: =I6+F6+E6 -> 87.694032 | K6: =A6*J6 -> 438.47016
A7: 6 | B7: 8724252 | C7: 7275748 | D7: =C7/2.5 -> 2910299.2 | E7: =(D7/60)/10000 -> 4.8504987 | F7: =(B7*2)/1000000 -> 17.448504 | G7: =IFERROR(B7+C7,0) -> 16000000 | H7: =SUM($G$2:G7) -> 94351469 | I7: =((H7/2.5)/48)/10000 -> 78.626224 | J7: =I7+F7+E7 -> 100.92523 | K7: =A7*J7 -> 605.55136
A8: 7 | B8: 9600000 | C8: 5840690 | D8: =C8/2.5 -> 2336276 | E8: =(D8/60)/10000 -> 3.8937933 | F8: =(B8*2)/1000000 -> 19.2 | G8: =IFERROR(B8+C8,0) -> 15440690 | H8: =SUM($G$2:G8) -> 109792159 | I8: =((H8/2.5)/48)/10000 -> 91.493466 | J8: =I8+F8+E8 -> 114.58726 | K8: =A8*J8 -> 802.11081
A9: 8 | B9: 9600000 | C9: 4845211 | D9: =C9/2.5 -> 1938084.4 | E9: =(D9/60)/10000 -> 3.2301407 | F9: =(B9*2)/1000000 -> 19.2 | G9: =IFERROR(B9+C9,0) -> 14445211 | H9: =SUM($G$2:G9) -> 124237370 | I9: =((H9/2.5)/48)/10000 -> 103.53114 | J9: =I9+F9+E9 -> 125.96128 | K9: =A9*J9 -> 1007.6903
A10: 9 | B10: 9600000 | C10: 4827335 | D10: =C10/2.5 -> 1930934 | E10: =(D10/60)/10000 -> 3.2182233 | F10: =(B10*2)/1000000 -> 19.2 | G10: =IFERROR(B10+C10,0) -> 14427335 | H10: =SUM($G$2:G10) -> 138664705 | I10: =((H10/2.5)/48)/10000 -> 115.55392 | J10: =I10+F10+E10 -> 137.97214 | K10: =A10*J10 -> 1241.7493
A11: 10 | B11: 9600000 | C11: 4660960 | D11: =C11/2.5 -> 1864384 | E11: =(D11/60)/10000 -> 3.1073067 | F11: =(B11*2)/1000000 -> 19.2 | G11: =IFERROR(B11+C11,0) -> 14260960 | H11: =SUM($G$2:G11) -> 152925665 | I11: =((H11/2.5)/48)/10000 -> 127.43805 | J11: =I11+F11+E11 -> 149.74536 | K11: =A11*J11 -> 1497.4536
A12: 11 | B12: 9600000 | C12: 5780301 | D12: =C12/2.5 -> 2312120.4 | E12: =(D12/60)/10000 -> 3.853534 | F12: =(B12*2)/1000000 -> 19.2 | G12: =IFERROR(B12+C12,0) -> 15380301 | H12: =SUM($G$2:G12) -> 168305966 | I12: =((H12/2.5)/48)/10000 -> 140.25497 | J12: =I12+F12+E12 -> 163.30851 | K12: =A12*J12 -> 1796.3936
A13: 12 | B13: 9600000 | C13: 6094455 | D13: =C13/2.5 -> 2437782 | E13: =(D13/60)/10000 -> 4.06297 | F13: =(B13*2)/1000000 -> 19.2 | G13: =IFERROR(B13+C13,0) -> 15694455 | H13: =SUM($G$2:G13) -> 184000421 | I13: =((H13/2.5)/48)/10000 -> 153.33368 | J13: =I13+F13+E13 -> 176.59665 | K13: =A13*J13 -> 2119.1599
... A29: 28 | B29: 5282538 | C29: 7913265 | D29: =C29/2.5 -> 3165306 | E29: =(D29/60)/10000 -> 5.27551 | F29: =(B29*2)/1000000 -> 10.565076 | G29: =IFERROR(B29+C29,0) -> 13195803 | H29: =SUM($G$2:G29) -> 437191681 | I29: =((H29/2.5)/48)/10000 -> 364.3264 | J29: =I29+F29+E29 -> 380.16699 | K29: =A29*J29 -> 10644.676
C35: =SUM(C2:C33) -> 226795520
H37: Key Outputs | I37: Total Land Occupation (ha·year) | J37: =MAX(K2:K33) -> 10644.676
I38: Max Total Area Used (ha) | J38: =MAX(J2:J33) -> 380.16699
G44: Parameters | H44: Units | I44: Value
G45: Haul Road Width | H45: m | I45: 26
G46: Haul Road Gradient | H46: % | I46: 10
G47: Mining Bench Height | H47: m | I47: 10
G48: Safety Berm Width | H48: m | I48: 8
G49: Batter Angle | H49: degrees | I49: 60
G50: Projection Angle | H50: degrees | I50: 18.5
G51: Density | I51: 2.5
G52: Level Height | H52: m | I52: 10
G53: Average dump hieght | H53: m | I53: 60
G54: K_leach | H54: ha per Mt ore | I54: 2
G55: avg. pit depth | H55: m | I55: 48
A60: 1 | B60: 9600000 | C60: 5625539 | D60: 0.59 | E60: 2.3391 | F60: 804494567 | G60: 731358697
A61: 2 | B61: 9600000 | C61: 5706793 | D61: 0.59 | E61: 1.7262 | F61: 531898300 | G61: 439585372
A62: 3 | B62: 9600000 | C62: 6219137 | D62: 0.65 | E62: 2.0647 | F62: 680634383 | G62: 511370686
A63: 4 | B63: 9454100 | C63: 6545900 | D63: 0.69 | E63: 2.4493 | F63: 837178181 | G63: 571803962
A64: 5 | B64: 8800856 | C64: 7199144 | D64: 0.82 | E64: 2.521 | F64: 804915972 | G64: 499789490
A65: 6 | B65: 8724252 | C65: 7275748 | D65: 0.83 | E65: 2.4579 | F65: 771962441 | G65: 435752673
A66: 7 | B66: 9600000 | C66: 5840690 | D66: 0.61 | E66: 2.4591 | F66: 857110598 | G66: 439833261
A67: 8 | B67: 9600000 | C67: 4845211 | D67: 0.5 | E67: 2.3533 | F67: 813364064 | G67: 379440338
A68: 9 | B68: 9600000 | C68: 4827335 | D68: 0.5 | E68: 2.3554 | F68: 814357877 | G68: 345367236
A69: 10 | B69: 9600000 | C69: 4660960 | D69: 0.49 | E69: 2.3965 | F69: 833128946 | G69: 321207275
A70: 11 | B70: 9600000 | C70: 5780301 | D70: 0.6 | E70: 2.4816 | F70: 867298644 | G70: 303982884
...

Sheet Schedule_9
A1: Year | B1: Ore (t) | C1: Waste (t) | D1: Waste (m^3) | E1: Dumps Area (ha) | F1: Leach Facility Area (ha) | G1: Total Material Mined (t) | H1: Cumulative Material (t) | I1: Estimated pit area (ha) | J1: Disturbed Area (ha) | K1: Land Occupation (ha·year)
A2: 1 | B2: 10500000 | C2: 6191049 | D2: =C2/2.5 -> 2476419.6 | E2: =(D2/60)/10000 -> 4.127366 | F2: =(B2*2)/1000000 -> 21 | G2: =IFERROR(B2+C2,0) -> 16691049 | H2: =SUM($G$2:G2) -> 16691049 | I2: =((H2/2.5)/48)/10000 -> 13.909207 | J2: =I2+F2+E2 -> 39.036574 | K2: =A2*J2 -> 39.036574
A3: 2 | B3: 10500000 | C3: 6327559 | D3: =C3/2.5 -> 2531023.6 | E3: =(D3/60)/10000 -> 4.2183727 | F3: =(B3*2)/1000000 -> 21 | G3: =IFERROR(B3+C3,0) -> 16827559 | H3: =SUM($G$2:G3) -> 33518608 | I3: =((H3/2.5)/48)/10000 -> 27.932173 | J3: =I3+F3+E3 -> 53.150546 | K3: =A3*J3 -> 106.30109
A4: 3 | B4: 10496812 | C4: 7003188 | D4: =C4/2.5 -> 2801275.2 | E4: =(D4/60)/10000 -> 4.668792 | F4: =(B4*2)/1000000 -> 20.993624 | G4: =IFERROR(B4+C4,0) -> 17500000 | H4: =SUM($G$2:G4) -> 51018608 | I4: =((H4/2.5)/48)/10000 -> 42.515507 | J4: =I4+F4+E4 -> 68.177923 | K4: =A4*J4 -> 204.53377
A5: 4 | B5: 10150747 | C5: 7349253 | D5: =C5/2.5 -> 2939701.2 | E5: =(D5/60)/10000 -> 4.899502 | F5: =(B5*2)/1000000 -> 20.301494 | G5: =IFERROR(B5+C5,0) -> 17500000 | H5: =SUM($G$2:G5) -> 68518608 | I5: =((H5/2.5)/48)/10000 -> 57.09884 | J5: =I5+F5+E5 -> 82.299836 | K5: =A5*J5 -> 329.19934
A6: 5 | B6: 9326528 | C6: 8173472 | D6: =C6/2.5 -> 3269388.8 | E6: =(D6/60)/10000 -> 5.4489813 | F6: =(B6*2)/1000000 -> 18.653056 | G6: =IFERROR(B6+C6,0) -> 17500000 | H6: =SUM($G$2:G6) -> 86018608 | I6: =((H6/2.5)/48)/10000 -> 71.682173 | J6: =I6+F6+E6 -> 95.784211 | K6: =A6*J6 -> 478.92105
A7: 6 | B7: 10131772 | C7: 7368228 | D7: =C7/2.5 -> 2947291.2 | E7: =(D7/60)/10000 -> 4.912152 | F7: =(B7*2)/1000000 -> 20.263544 | G7: =IFERROR(B7+C7,0) -> 17500000 | H7: =SUM($G$2:G7) -> 103518608 | I7: =((H7/2.5)/48)/10000 -> 86.265507 | J7: =I7+F7+E7 -> 111.4412 | K7: =A7*J7 -> 668.64722
A8: 7 | B8: 10500000 | C8: 5558252 | D8: =C8/2.5 -> 2223300.8 | E8: =(D8/60)/10000 -> 3.7055013 | F8: =(B8*2)/1000000 -> 21 | G8: =IFERROR(B8+C8,0) -> 16058252 | H8: =SUM($G$2:G8) -> 119576860 | I8: =((H8/2.5)/48)/10000 -> 99.647383 | J8: =I8+F8+E8 -> 124.35288 | K8: =A8*J8 -> 870.47019
A9: 8 | B9: 10500000 | C9: 5419607 | D9: =C9/2.5 -> 2167842.8 | E9: =(D9/60)/10000 -> 3.6130713 | F9: =(B9*2)/1000000 -> 21 | G9: =IFERROR(B9+C9,0) -> 15919607 | H9: =SUM($G$2:G9) -> 135496467 | I9: =((H9/2.5)/48)/10000 -> 112.91372 | J9: =I9+F9+E9 -> 137.52679 | K9: =A9*J9 -> 1100.2144
A10: 9 | B10: 10500000 | C10: 5179698 | D10: =C10/2.5 -> 2071879.2 | E10: =(D10/60)/10000 -> 3.453132 | F10: =(B10*2)/1000000 -> 21 | G10: =IFERROR(B10+C10,0) -> 15679698 | H10: =SUM($G$2:G10) -> 151176165 | I10: =((H10/2.5)/48)/10000 -> 125.98014 | J10: =I10+F10+E10 -> 150.43327 | K10: =A10*J10 -> 1353.8994
A11: 10 | B11: 10498760 | C11: 7001240 | D11: =C11/2.5 -> 2800496 | E11: =(D11/60)/10000 -> 4.6674933 | F11: =(B11*2)/1000000 -> 20.99752 | G11: =IFERROR(B11+C11,0) -> 17500000 | H11: =SUM($G$2:G11) -> 168676165 | I11: =((H11/2.5)/48)/10000 -> 140.56347 | J11: =I11+F11+E11 -> 166.22848 | K11: =A11*J11 -> 1662.2848
A12: 11 | B12: 10500000 | C12: 6977618 | D12: =C12/2.5 -> 2791047.2 | E12: =(D12/60)/10000 -> 4.6517453 | F12: =(B12*2)/1000000 -> 21 | G12: =IFERROR(B12+C12,0) -> 17477618 | H12: =SUM($G$2:G12) -> 186153783 | I12: =((H12/2.5)/48)/10000 -> 155.12815 | J12: =I12+F12+E12 -> 180.7799 | K12: =A12*J12 -> 1988.5789
A13: 12 | B13: 10298199 | C13: 7201801 | D13: =C13/2.5 -> 2880720.4 | E13: =(D13/60)/10000 -> 4.8012007 | F13: =(B13*2)/1000000 -> 20.596398 | G13: =IFERROR(B13+C13,0) -> 17500000 | H13: =SUM($G$2:G13) -> 203653783 | I13: =((H13/2.5)/48)/10000 -> 169.71149 | J13: =I13+F13+E13 -> 195.10908 | K13: =A13*J13 -> 2341.309
... A29: 28 | B29: 6190356 | C29: 9437621 | D29: =C29/2.5 -> 3775048.4 | E29: =(D29/60)/10000 -> 6.2917473 | F29: =(B29*2)/1000000 -> 12.380712 | G29: =IFERROR(B29+C29,0) -> 15627977 | H29: =SUM($G$2:G29) -> 481781760 | I29: =((H29/2.5)/48)/10000 -> 401.4848 | J29: =I29+F29+E29 -> 420.15726 | K29: =A29*J29 -> 11764.403
C35: =SUM(C2:C33) -> 259752957
H37: Key Outputs | I37: Total Land Occupation (ha·year) | J37: =MAX(K2:K33) -> 11764.403
I38: Max Total Area Used (ha) | J38: =MAX(J2:J33) -> 420.15726
G44: Parameters | H44: Units | I44: Value
G45: Haul Road Width | H45: m | I45: 26
G46: Haul Road Gradient | H46: % | I46: 10
G47: Mining Bench Height | H47: m | I47: 10
G48: Safety Berm Width | H48: m | I48: 8
G49: Batter Angle | H49: degrees | I49: 60
G50: Projection Angle | H50: degrees | I50: 18.5
G51: Density | I51: 2.5
G52: Level Height | H52: m | I52: 10
G53: Average dump hieght | H53: m | I53: 60
G54: K_leach | H54: ha per Mt ore | I54: 2
G55: avg. pit depth | H55: m | I55: 48
A60: 1 | B60: 10500000 | C60: 6191049 | D60: 0.59 | E60: 2.2932 | F60: 857457389 | G60: 779506717
A61: 2 | B61: 10500000 | C61: 6327559 | D61: 0.6 | E61: 1.7402 | F61: 588280146 | G61: 486181939
A62: 3 | B62: 10496812 | C62: 7003188 | D62: 0.67 | E62: 2.1725 | F62: 795927480 | G62: 597992096
A63: 4 | B63: 10150747 | C63: 7349253 | D63: 0.72 | E63: 2.5081 | F63: 925430255 | G63: 632081316
A64: 5 | B64: 9326528 | C64: 8173472 | D64: 0.88 | E64: 2.488 | F64: 836971164 | G64: 519693243
A65: 6 | B65: 10131772 | C65: 7368228 | D65: 0.73 | E65: 2.5016 | F65: 920530388 | G65: 519615406
A66: 7 | B66: 10500000 | C66: 5558252 | D66: 0.53 | E66: 2.3798 | F66: 901618414 | G66: 462672809
A67: 8 | B67: 10500000 | C67: 5419607 | D67: 0.52 | E67: 2.3569 | F67: 890963281 | G67: 415640946
A68: 9 | B68: 10500000 | C68: 5179698 | D68: 0.49 | E68: 2.3864 | F68: 906095013 | G68: 384272737
A69: 10 | B69: 10498760 | C69: 7001240 | D69: 0.67 | E69: 2.4697 | F69: 940483433 | G69: 362597077
A70: 11 | B70: 10500000 | C70: 6977618 | D70: 0.66 | E70: 2.5146 | F70: 962463962 | G70: 337337747
...

Sheet Schedule_10
A1: Year | B1: Ore (t) | C1: Waste (t) | D1: Waste (m^3) | E1: Dumps Area (ha) | F1: Leach Facility Area (ha) | G1: Total Material Mined (t) | H1: Cumulative Material (t) | I1: Estimated pit area (ha) | J1: Disturbed Area (ha) | K1: Land Occupation (ha·year)
A2: 1 | B2: 11400000 | C2: 6724635 | D2: =C2/2.5 -> 2689854 | E2: =(D2/60)/10000 -> 4.48309 | F2: =(B2*2)/1000000 -> 22.8 | G2: =IFERROR(B2+C2,0) -> 18124635 | H2: =SUM($G$2:G2) -> 18124635 | I2: =((H2/2.5)/49)/10000 -> 14.79562 | J2: =I2+F2+E2 -> 42.07871 | K2: =A2*J2 -> 42.07871
A3: 2 | B3: 11400000 | C3: 6884902 | D3: =C3/2.5 -> 2753960.8 | E3: =(D3/60)/10000 -> 4.5899347 | F3: =(B3*2)/1000000 -> 22.8 | G3: =IFERROR(B3+C3,0) -> 18284902 | H3: =SUM($G$2:G3) -> 36409537 | I3: =((H3/2.5)/49)/10000 -> 29.722071 | J3: =I3+F3+E3 -> 57.112006 | K3: =A3*J3 -> 114.22401
A4: 3 | B4: 11348756 | C4: 7651244 | D4: =C4/2.5 -> 3060497.6 | E4: =(D4/60)/10000 -> 5.1008293 | F4: =(B4*2)/1000000 -> 22.697512 | G4: =IFERROR(B4+C4,0) -> 19000000 | H4: =SUM($G$2:G4) -> 55409537 | I4: =((H4/2.5)/49)/10000 -> 45.232275 | J4: =I4+F4+E4 -> 73.030616 | K4: =A4*J4 -> 219.09185
A5: 4 | B5: 10813836 | C5: 8186164 | D5: =C5/2.5 -> 3274465.6 | E5: =(D5/60)/10000 -> 5.4574427 | F5: =(B5*2)/1000000 -> 21.627672 | G5: =IFERROR(B5+C5,0) -> 19000000 | H5: =SUM($G$2:G5) -> 74409537 | I5: =((H5/2.5)/49)/10000 -> 60.742479 | J5: =I5+F5+E5 -> 87.827594 | K5: =A5*J5 -> 351.31038
A6: 5 | B6: 10251892 | C6: 8748108 | D6: =C6/2.5 -> 3499243.2 | E6: =(D6/60)/10000 -> 5.832072 | F6: =(B6*2)/1000000 -> 20.503784 | G6: =IFERROR(B6+C6,0) -> 19000000 | H6: =SUM($G$2:G6) -> 93409537 | I6: =((H6/2.5)/49)/10000 -> 76.252683 | J6: =I6+F6+E6 -> 102.58854 | K6: =A6*J6 -> 512.9427
A7: 6 | B7: 11400000 | C7: 6903982 | D7: =C7/2.5 -> 2761592.8 | E7: =(D7/60)/10000 -> 4.6026547 | F7: =(B7*2)/1000000 -> 22.8 | G7: =IFERROR(B7+C7,0) -> 18303982 | H7: =SUM($G$2:G7) -> 111713519 | I7: =((H7/2.5)/49)/10000 -> 91.194709 | J7: =I7+F7+E7 -> 118.59736 | K7: =A7*J7 -> 711.58418
A8: 7 | B8: 11400000 | C8: 5879981 | D8: =C8/2.5 -> 2351992.4 | E8: =(D8/60)/10000 -> 3.9199873 | F8: =(B8*2)/1000000 -> 22.8 | G8: =IFERROR(B8+C8,0) -> 17279981 | H8: =SUM($G$2:G8) -> 128993500 | I8: =((H8/2.5)/49)/10000 -> 105.30082 | J8: =I8+F8+E8 -> 132.0208 | K8: =A8*J8 -> 924.14563
A9: 8 | B9: 11400000 | C9: 6032777 | D9: =C9/2.5 -> 2413110.8 | E9: =(D9/60)/10000 -> 4.0218513 | F9: =(B9*2)/1000000 -> 22.8 | G9: =IFERROR(B9+C9,0) -> 17432777 | H9: =SUM($G$2:G9) -> 146426277 | I9: =((H9/2.5)/49)/10000 -> 119.53165 | J9: =I9+F9+E9 -> 146.35351 | K9: =A9*J9 -> 1170.828
A10: 9 | B10: 11400000 | C10: 7317442 | D10: =C10/2.5 -> 2926976.8 | E10: =(D10/60)/10000 -> 4.8782947 | F10: =(B10*2)/1000000 -> 22.8 | G10: =IFERROR(B10+C10,0) -> 18717442 | H10: =SUM($G$2:G10) -> 165143719 | I10: =((H10/2.5)/49)/10000 -> 134.8112 | J10: =I10+F10+E10 -> 162.48949 | K10: =A10*J10 -> 1462.4054
A11: 10 | B11: 11400000 | C11: 7591410 | D11: =C11/2.5 -> 3036564 | E11: =(D11/60)/10000 -> 5.06094 | F11: =(B11*2)/1000000 -> 22.8 | G11: =IFERROR(B11+C11,0) -> 18991410 | H11: =SUM($G$2:G11) -> 184135129 | I11: =((H11/2.5)/49)/10000 -> 150.31439 | J11: =I11+F11+E11 -> 178.17533 | K11: =A11*J11 -> 1781.7533
A12: 11 | B12: 11389472 | C12: 7610528 | D12: =C12/2.5 -> 3044211.2 | E12: =(D12/60)/10000 -> 5.0736853 | F12: =(B12*2)/1000000 -> 22.778944 | G12: =IFERROR(B12+C12,0) -> 19000000 | H12: =SUM($G$2:G12) -> 203135129 | I12: =((H12/2.5)/49)/10000 -> 165.8246 | J12: =I12+F12+E12 -> 193.67722 | K12: =A12*J12 -> 2130.4495
A13: 12 | B13: 9749950 | C13: 9250050 | D13: =C13/2.5 -> 3700020 | E13: =(D13/60)/10000 -> 6.1667 | F13: =(B13*2)/1000000 -> 19.4999 | G13: =IFERROR(B13+C13,0) -> 19000000 | H13: =SUM($G$2:G13) -> 222135129 | I13: =((H13/2.5)/49)/10000 -> 181.3348 | J13: =I13+F13+E13 -> 207.0014 | K13: =A13*J13 -> 2484.0168
... A28: 27 | B28: 3932802 | C28: 5813670 | D28: =C28/2.5 -> 2325468 | E28: =(D28/60)/10000 -> 3.87578 | F28: =(B28*2)/1000000 -> 7.865604 | G28: =IFERROR(B28+C28,0) -> 9746472 | H28: =SUM($G$2:G28) -> 497881601 | I28: =((H28/2.5)/49)/10000 -> 406.43396 | J28: =I28+F28+E28 -> 418.17534 | K28: =A28*J28 -> 11290.734
C35: =SUM(C2:C33) -> 273262081
H37: Key Outputs | I37: Total Land Occupation (ha·year) | J37: =MAX(K2:K33) -> 11290.734
I38: Max Total Area Used (ha) | J38: =MAX(J2:J33) -> 420.55853
G44: Parameters | H44: Units | I44: Value
G45: Haul Road Width | H45: m | I45: 26
G46: Haul Road Gradient | H46: % | I46: 10
G47: Mining Bench Height | H47: m | I47: 10
G48: Safety Berm Width | H48: m | I48: 8
G49: Batter Angle | H49: degrees | I49: 60
G50: Projection Angle | H50: degrees | I50: 18.5
G51: Density | I51: 2.5
G52: Level Height | H52: m | I52: 10
G53: Average dump hieght | H53: m | I53: 60
G54: K_leach | H54: ha per Mt ore | I54: 2
G55: avg. pit depth | H55: m | I55: 48
A60: 1 | B60: 11400000 | C60: 6724635 | D60: 0.59 | E60: 2.2476 | F60: 906891620 | G60: 824446927
A61: 2 | B61: 11400000 | C61: 6884902 | D61: 0.6 | E61: 1.7846 | F61: 662132136 | G61: 547216641
A62: 3 | B62: 11348756 | C62: 7651244 | D62: 0.67 | E62: 2.2746 | F62: 913885631 | G62: 686615801
A63: 4 | B63: 10813836 | C63: 8186164 | D63: 0.76 | E63: 2.5314 | F63: 996357577 | G63: 680525632
A64: 5 | B64: 10251892 | C64: 8748108 | D64: 0.85 | E64: 2.4693 | F64: 911904422 | G64: 566220900
A65: 6 | B65: 11400000 | C65: 6903982 | D65: 0.61 | E65: 2.4576 | F65: 1017101329 | G65: 574127185
A66: 7 | B66: 11400000 | C66: 5879981 | D66: 0.52 | E66: 2.3635 | F66: 970841575 | G66: 498195236
A67: 8 | B67: 11400000 | C67: 6032777 | D67: 0.53 | E67: 2.3719 | F67: 974761346 | G67: 454733362
A68: 9 | B68: 11400000 | C68: 7317442 | D68: 0.64 | E68: 2.4497 | F68: 1011581744 | G68: 429009408
A69: 10 | B69: 11400000 | C69: 7591410 | D69: 0.67 | E69: 2.4754 | F69: 1024242833 | G69: 394889951
