Workbook

Sheet schedule_1 
A1: Year | B1: Ore (t) | C1: Grade (g/t) | D1: Recovery (override, optional) | E1: Metal Price (override, optional) | F1: Metal Produced (oz) | G1: Revenue (USD) | H1: Severance Tax (USD) | I1: Discount Factor | J1: PV(Severance Tax) (USD) | K1: Cumulative Revenue (USD) | L1: Payable Metal (oz) | M1: NSR ($) | N1: Royalty ($) | O1: PV(Royalty)
A2: 1 | B2: 13000000 | C2: 2.02 | D2: 0.82 | E2: 1600 | F2: =IFERROR(B2*C2*IF(D2="", Parameters!$B$2, D2)/Parameters!$B$6, 0) -> 692307.94 | G2: =F2*IF(E2="", Parameters!$B$2, E2) -> 1.1076927e+09 | H2: =G2*Parameters!$B$4 -> 28800010 | I2: =1/POWER(1+Parameters!$B$5, A2) -> 0.90909091 | J2: =H2*I2 -> 26181828 | K2: =SUM($G$2:G2) -> 1.1076927e+09 | L2: =F2*0.95 -> 657692.54 | M2: =L2*IF(E2="",Parameters!$B$2,E2) -> 1.0523081e+09 | N2: =M2*0.0251 -> 26412933 | O2: =N2*I2 -> 24011757
A3: 2 | B3: 13000000 | C3: 2.02 | D3: 0.82 | E3: 1600 | F3: =IFERROR(B3*C3*IF(D3="", Parameters!$B$2, D3)/Parameters!$B$6, 0) -> 692307.94 | G3: =F3*IF(E3="", Parameters!$B$2, E3) -> 1.1076927e+09 | H3: =G3*Parameters!$B$4 -> 28800010 | I3: =1/POWER(1+Parameters!$B$5, A3) -> 0.82644628 | J3: =H3*I3 -> 23801661 | K3: =SUM($G$2:G3) -> 2.2153854e+09 | L3: =F3*0.95 -> 657692.54 | M3: =L3*IF(E3="",Parameters!$B$2,E3) -> 1.0523081e+09 | N3: =M3*0.0251 -> 26412933 | O3: =N3*I3 -> 21828870
A4: 3 | B4: 13000000 | C4: 2.02 | D4: 0.82 | E4: 1600 | F4: =IFERROR(B4*C4*IF(D4="", Parameters!$B$2, D4)/Parameters!$B$6, 0) -> 692307.94 | G4: =F4*IF(E4="", Parameters!$B$2, E4) -> 1.1076927e+09 | H4: =G4*Parameters!$B$4 -> 28800010 | I4: =1/POWER(1+Parameters!$B$5, A4) -> 0.7513148 | J4: =H4*I4 -> 21637874 | K4: =SUM($G$2:G4) -> 3.3230781e+09 | L4: =F4*0.95 -> 657692.54 | M4: =L4*IF(E4="",Parameters!$B$2,E4) -> 1.0523081e+09 | N4: =M4*0.0251 -> 26412933 | O4: =N4*I4 -> 19844427
A5: 4 | B5: 13000000 | C5: 2.02 | D5: 0.82 | E5: 1600 | F5: =IFERROR(B5*C5*IF(D5="", Parameters!$B$2, D5)/Parameters!$B$6, 0) -> 692307.94 | G5: =F5*IF(E5="", Parameters!$B$2, E5) -> 1.1076927e+09 | H5: =G5*Parameters!$B$4 -> 28800010 | I5: =1/POWER(1+Parameters!$B$5, A5) -> 0.68301346 | J5: =H5*I5 -> 19670795 | K5: =SUM($G$2:G5) -> 4.4307708e+09 | L5: =F5*0.95 -> 657692.54 | M5: =L5*IF(E5="",Parameters!$B$2,E5) -> 1.0523081e+09 | N5: =M5*0.0251 -> 26412933 | O5: =N5*I5 -> 18040388
A6: 5 | B6: 13000000 | C6: 2.02 | D6: 0.82 | E6: 1600 | F6: =IFERROR(B6*C6*IF(D6="", Parameters!$B$2, D6)/Parameters!$B$6, 0) -> 692307.94 | G6: =F6*IF(E6="", Parameters!$B$2, E6) -> 1.1076927e+09 | H6: =G6*Parameters!$B$4 -> 28800010 | I6: =1/POWER(1+Parameters!$B$5, A6) -> 0.62092132 | J6: =H6*I6 -> 17882540 | K6: =SUM($G$2:G6) -> 5.5384635e+09 | L6: =F6*0.95 -> 657692.54 | M6: =L6*IF(E6="",Parameters!$B$2,E6) -> 1.0523081e+09 | N6: =M6*0.0251 -> 26412933 | O6: =N6*I6 -> 16400353
A7: 6 | B7: 13000000 | C7: 2.02 | D7: 0.82 | E7: 1600 | F7: =IFERROR(B7*C7*IF(D7="", Parameters!$B$2, D7)/Parameters!$B$6, 0) -> 692307.94 | G7: =F7*IF(E7="", Parameters!$B$2, E7) -> 1.1076927e+09 | H7: =G7*Parameters!$B$4 -> 28800010 | I7: =1/POWER(1+Parameters!$B$5, A7) -> 0.56447393 | J7: =H7*I7 -> 16256855 | K7: =SUM($G$2:G7) -> 6.6461562e+09 | L7: =F7*0.95 -> 657692.54 | M7: =L7*IF(E7="",Parameters!$B$2,E7) -> 1.0523081e+09 | N7: =M7*0.0251 -> 26412933 | O7: =N7*I7 -> 14909412
A8: 7 | B8: 13000000 | C8: 2.02 | D8: 0.82 | E8: 1600 | F8: =IFERROR(B8*C8*IF(D8="", Parameters!$B$2, D8)/Parameters!$B$6, 0) -> 692307.94 | G8: =F8*IF(E8="", Parameters!$B$2, E8) -> 1.1076927e+09 | H8: =G8*Parameters!$B$4 -> 28800010 | I8: =1/POWER(1+Parameters!$B$5, A8) -> 0.51315812 | J8: =H8*I8 -> 14778959 | K8: =SUM($G$2:G8) -> 7.7538489e+09 | L8: =F8*0.95 -> 657692.54 | M8: =L8*IF(E8="",Parameters!$B$2,E8) -> 1.0523081e+09 | N8: =M8*0.0251 -> 26412933 | O8: =N8*I8 -> 13554011
A9: 8 | B9: 13000000 | C9: 2.02 | D9: 0.82 | E9: 1600 | F9: =IFERROR(B9*C9*IF(D9="", Parameters!$B$2, D9)/Parameters!$B$6, 0) -> 692307.94 | G9: =F9*IF(E9="", Parameters!$B$2, E9) -> 1.1076927e+09 | H9: =G9*Parameters!$B$4 -> 28800010 | I9: =1/POWER(1+Parameters!$B$5, A9) -> 0.46650738 | J9: =H9*I9 -> 13435417 | K9: =SUM($G$2:G9) -> 8.8615416e+09 | L9: =F9*0.95 -> 657692.54 | M9: =L9*IF(E9="",Parameters!$B$2,E9) -> 1.0523081e+09 | N9: =M9*0.0251 -> 26412933 | O9: =N9*I9 -> 12321828
A10: 9 | B10: 13000000 | C10: 2.02 | D10: 0.82 | E10: 1600 | F10: =IFERROR(B10*C10*IF(D10="", Parameters!$B$2, D10)/Parameters!$B$6, 0) -> 692307.94 | G10: =F10*IF(E10="", Parameters!$B$2, E10) -> 1.1076927e+09 | H10: =G10*Parameters!$B$4 -> 28800010 | I10: =1/POWER(1+Parameters!$B$5, A10) -> 0.42409762 | J10: =H10*I10 -> 12214016 | K10: =SUM($G$2:G10) -> 9.9692343e+09 | L10: =F10*0.95 -> 657692.54 | M10: =L10*IF(E10="",Parameters!$B$2,E10) -> 1.0523081e+09 | N10: =M10*0.0251 -> 26412933 | O10: =N10*I10 -> 11201662
A11: 10 | B11: 13000000 | C11: 2.02 | D11: 0.82 | E11: 1600 | F11: =IFERROR(B11*C11*IF(D11="", Parameters!$B$2, D11)/Parameters!$B$6, 0) -> 692307.94 | G11: =F11*IF(E11="", Parameters!$B$2, E11) -> 1.1076927e+09 | H11: =G11*Parameters!$B$4 -> 28800010 | I11: =1/POWER(1+Parameters!$B$5, A11) -> 0.38554329 | J11: =H11*I11 -> 11103651 | K11: =SUM($G$2:G11) -> 1.1076927e+10 | L11: =F11*0.95 -> 657692.54 | M11: =L11*IF(E11="",Parameters!$B$2,E11) -> 1.0523081e+09 | N11: =M11*0.0251 -> 26412933 | O11: =N11*I11 -> 10183329
A12: 11 | B12: 13000000 | C12: 2.02 | D12: 0.82 | E12: 1600 | F12: =IFERROR(B12*C12*IF(D12="", Parameters!$B$2, D12)/Parameters!$B$6, 0) -> 692307.94 | G12: =F12*IF(E12="", Parameters!$B$2, E12) -> 1.1076927e+09 | H12: =G12*Parameters!$B$4 -> 28800010 | I12: =1/POWER(1+Parameters!$B$5, A12) -> 0.3504939 | J12: =H12*I12 -> 10094228 | K12: =SUM($G$2:G12) -> 1.218462e+10 | L12: =F12*0.95 -> 657692.54 | M12: =L12*IF(E12="",Parameters!$B$2,E12) -> 1.0523081e+09 | N12: =M12*0.0251 -> 26412933 | O12: =N12*I12 -> 9257571.7
A13: 12 | B13: 13000000 | C13: 2.02 | D13: 0.82 | E13: 1600 | F13: =IFERROR(B13*C13*IF(D13="", Parameters!$B$2, D13)/Parameters!$B$6, 0) -> 692307.94 | G13: =F13*IF(E13="", Parameters!$B$2, E13) -> 1.1076927e+09 | H13: =G13*Parameters!$B$4 -> 28800010 | I13: =1/POWER(1+Parameters!$B$5, A13) -> 0.31863082 | J13: =H13*I13 -> 9176570.8 | K13: =SUM($G$2:G13) -> 1.3292312e+10 | L13: =F13*0.95 -> 657692.54 | M13: =L13*IF(E13="",Parameters!$B$2,E13) -> 1.0523081e+09 | N13: =M13*0.0251 -> 26412933 | O13: =N13*I13 -> 8415974.3
... A33: 32 | B33: 13000000 | C33: 2.02 | D33: 0.82 | E33: 1600 | F33: =IFERROR(B33*C33*IF(D33="", Parameters!$B$2, D33)/Parameters!$B$6, 0) -> 692307.94 | G33: =F33*IF(E33="", Parameters!$B$2, E33) -> 1.1076927e+09 | H33: =G33*Parameters!$B$4 -> 28800010 | I33: =1/POWER(1+Parameters!$B$5, A33) -> 0.047362441 | J33: =H33*I33 -> 1364038.8 | K33: =SUM($G$2:G33) -> 3.5446167e+10 | L33: =F33*0.95 -> 657692.54 | M33: =L33*IF(E33="",Parameters!$B$2,E33) -> 1.0523081e+09 | N33: =M33*0.0251 -> 26412933 | O33: =N33*I33 -> 1250981
F39: Totals / Key Outputs | G39: =SUM(G2:G33) -> 3.5446167e+10 | H39: =SUM(H2:H33) -> 9.2160033e+08 | J39: =SUM(J2:J33) -> 2.7435972e+08 | O39: =SUM(O2:O33) -> 2.5161952e+08
F40: Total Revenue (USD) | G40: =G39 -> 3.5446167e+10
F41: Total Severance Tax (USD) | G41: =H39 -> 9.2160033e+08
F42: PV(Severance Tax) (USD) | G42: =J39 -> 2.7435972e+08

Sheet schedule_2
A1: Year | B1: Ore (t) | C1: Grade (g/t) | D1: Recovery (override, optional) | E1: Metal Price (override, optional) | F1: Metal Produced (oz) | G1: Revenue (USD) | H1: Severance Tax (USD) | I1: Discount Factor | J1: PV(Severance Tax) (USD) | K1: Cumulative Revenue (USD) | L1: Payable Metal (oz) | M1: NSR ($) | N1: Royalty ($) | O1: PV(Royalty)
A2: 1 | B2: 14000000 | C2: 1.952 | D2: 0.82 | E2: 1600 | F2: =IFERROR(B2*C2*IF(D2="", Parameters!$B$2, D2)/Parameters!$B$6, 0) -> 720464.26 | G2: =F2*IF(E2="", Parameters!$B$2, E2) -> 1.1527428e+09 | H2: =G2*Parameters!$B$4 -> 29971313 | I2: =1/POWER(1+Parameters!$B$5, A2) -> 0.90909091 | J2: =H2*I2 -> 27246648 | K2: =SUM($G$2:G2) -> 1.1527428e+09 | L2: =F2*0.95 -> 684441.04 | M2: =L2*IF(E2="",Parameters!$B$2,E2) -> 1.0951057e+09 | N2: =M2*0.0251 -> 27487152 | O2: =N2*I2 -> 24988320
A3: 2 | B3: 14000000 | C3: 1.952 | D3: 0.82 | E3: 1600 | F3: =IFERROR(B3*C3*IF(D3="", Parameters!$B$2, D3)/Parameters!$B$6, 0) -> 720464.26 | G3: =F3*IF(E3="", Parameters!$B$2, E3) -> 1.1527428e+09 | H3: =G3*Parameters!$B$4 -> 29971313 | I3: =1/POWER(1+Parameters!$B$5, A3) -> 0.82644628 | J3: =H3*I3 -> 24769680 | K3: =SUM($G$2:G3) -> 2.3054856e+09 | L3: =F3*0.95 -> 684441.04 | M3: =L3*IF(E3="",Parameters!$B$2,E3) -> 1.0951057e+09 | N3: =M3*0.0251 -> 27487152 | O3: =N3*I3 -> 22716655
A4: 3 | B4: 14000000 | C4: 1.952 | D4: 0.82 | E4: 1600 | F4: =IFERROR(B4*C4*IF(D4="", Parameters!$B$2, D4)/Parameters!$B$6, 0) -> 720464.26 | G4: =F4*IF(E4="", Parameters!$B$2, E4) -> 1.1527428e+09 | H4: =G4*Parameters!$B$4 -> 29971313 | I4: =1/POWER(1+Parameters!$B$5, A4) -> 0.7513148 | J4: =H4*I4 -> 22517891 | K4: =SUM($G$2:G4) -> 3.4582284e+09 | L4: =F4*0.95 -> 684441.04 | M4: =L4*IF(E4="",Parameters!$B$2,E4) -> 1.0951057e+09 | N4: =M4*0.0251 -> 27487152 | O4: =N4*I4 -> 20651504
A5: 4 | B5: 14000000 | C5: 1.952 | D5: 0.82 | E5: 1600 | F5: =IFERROR(B5*C5*IF(D5="", Parameters!$B$2, D5)/Parameters!$B$6, 0) -> 720464.26 | G5: =F5*IF(E5="", Parameters!$B$2, E5) -> 1.1527428e+09 | H5: =G5*Parameters!$B$4 -> 29971313 | I5: =1/POWER(1+Parameters!$B$5, A5) -> 0.68301346 | J5: =H5*I5 -> 20470810 | K5: =SUM($G$2:G5) -> 4.6109712e+09 | L5: =F5*0.95 -> 684441.04 | M5: =L5*IF(E5="",Parameters!$B$2,E5) -> 1.0951057e+09 | N5: =M5*0.0251 -> 27487152 | O5: =N5*I5 -> 18774095
A6: 5 | B6: 14000000 | C6: 1.952 | D6: 0.82 | E6: 1600 | F6: =IFERROR(B6*C6*IF(D6="", Parameters!$B$2, D6)/Parameters!$B$6, 0) -> 720464.26 | G6: =F6*IF(E6="", Parameters!$B$2, E6) -> 1.1527428e+09 | H6: =G6*Parameters!$B$4 -> 29971313 | I6: =1/POWER(1+Parameters!$B$5, A6) -> 0.62092132 | J6: =H6*I6 -> 18609827 | K6: =SUM($G$2:G6) -> 5.7637141e+09 | L6: =F6*0.95 -> 684441.04 | M6: =L6*IF(E6="",Parameters!$B$2,E6) -> 1.0951057e+09 | N6: =M6*0.0251 -> 27487152 | O6: =N6*I6 -> 17067359
A7: 6 | B7: 14000000 | C7: 1.952 | D7: 0.82 | E7: 1600 | F7: =IFERROR(B7*C7*IF(D7="", Parameters!$B$2, D7)/Parameters!$B$6, 0) -> 720464.26 | G7: =F7*IF(E7="", Parameters!$B$2, E7) -> 1.1527428e+09 | H7: =G7*Parameters!$B$4 -> 29971313 | I7: =1/POWER(1+Parameters!$B$5, A7) -> 0.56447393 | J7: =H7*I7 -> 16918025 | K7: =SUM($G$2:G7) -> 6.9164569e+09 | L7: =F7*0.95 -> 684441.04 | M7: =L7*IF(E7="",Parameters!$B$2,E7) -> 1.0951057e+09 | N7: =M7*0.0251 -> 27487152 | O7: =N7*I7 -> 15515781
A8: 7 | B8: 14000000 | C8: 1.952 | D8: 0.82 | E8: 1600 | F8: =IFERROR(B8*C8*IF(D8="", Parameters!$B$2, D8)/Parameters!$B$6, 0) -> 720464.26 | G8: =F8*IF(E8="", Parameters!$B$2, E8) -> 1.1527428e+09 | H8: =G8*Parameters!$B$4 -> 29971313 | I8: =1/POWER(1+Parameters!$B$5, A8) -> 0.51315812 | J8: =H8*I8 -> 15380023 | K8: =SUM($G$2:G8) -> 8.0691997e+09 | L8: =F8*0.95 -> 684441.04 | M8: =L8*IF(E8="",Parameters!$B$2,E8) -> 1.0951057e+09 | N8: =M8*0.0251 -> 27487152 | O8: =N8*I8 -> 14105255
A9: 8 | B9: 14000000 | C9: 1.952 | D9: 0.82 | E9: 1600 | F9: =IFERROR(B9*C9*IF(D9="", Parameters!$B$2, D9)/Parameters!$B$6, 0) -> 720464.26 | G9: =F9*IF(E9="", Parameters!$B$2, E9) -> 1.1527428e+09 | H9: =G9*Parameters!$B$4 -> 29971313 | I9: =1/POWER(1+Parameters!$B$5, A9) -> 0.46650738 | J9: =H9*I9 -> 13981839 | K9: =SUM($G$2:G9) -> 9.2219425e+09 | L9: =F9*0.95 -> 684441.04 | M9: =L9*IF(E9="",Parameters!$B$2,E9) -> 1.0951057e+09 | N9: =M9*0.0251 -> 27487152 | O9: =N9*I9 -> 12822959
A10: 9 | B10: 14000000 | C10: 1.952 | D10: 0.82 | E10: 1600 | F10: =IFERROR(B10*C10*IF(D10="", Parameters!$B$2, D10)/Parameters!$B$6, 0) -> 720464.26 | G10: =F10*IF(E10="", Parameters!$B$2, E10) -> 1.1527428e+09 | H10: =G10*Parameters!$B$4 -> 29971313 | I10: =1/POWER(1+Parameters!$B$5, A10) -> 0.42409762 | J10: =H10*I10 -> 12710762 | K10: =SUM($G$2:G10) -> 1.0374685e+10 | L10: =F10*0.95 -> 684441.04 | M10: =L10*IF(E10="",Parameters!$B$2,E10) -> 1.0951057e+09 | N10: =M10*0.0251 -> 27487152 | O10: =N10*I10 -> 11657236
A11: 10 | B11: 14000000 | C11: 1.952 | D11: 0.82 | E11: 1600 | F11: =IFERROR(B11*C11*IF(D11="", Parameters!$B$2, D11)/Parameters!$B$6, 0) -> 720464.26 | G11: =F11*IF(E11="", Parameters!$B$2, E11) -> 1.1527428e+09 | H11: =G11*Parameters!$B$4 -> 29971313 | I11: =1/POWER(1+Parameters!$B$5, A11) -> 0.38554329 | J11: =H11*I11 -> 11555239 | K11: =SUM($G$2:G11) -> 1.1527428e+10 | L11: =F11*0.95 -> 684441.04 | M11: =L11*IF(E11="",Parameters!$B$2,E11) -> 1.0951057e+09 | N11: =M11*0.0251 -> 27487152 | O11: =N11*I11 -> 10597487
A12: 11 | B12: 14000000 | C12: 1.952 | D12: 0.82 | E12: 1600 | F12: =IFERROR(B12*C12*IF(D12="", Parameters!$B$2, D12)/Parameters!$B$6, 0) -> 720464.26 | G12: =F12*IF(E12="", Parameters!$B$2, E12) -> 1.1527428e+09 | H12: =G12*Parameters!$B$4 -> 29971313 | I12: =1/POWER(1+Parameters!$B$5, A12) -> 0.3504939 | J12: =H12*I12 -> 10504762 | K12: =SUM($G$2:G12) -> 1.2680171e+10 | L12: =F12*0.95 -> 684441.04 | M12: =L12*IF(E12="",Parameters!$B$2,E12) -> 1.0951057e+09 | N12: =M12*0.0251 -> 27487152 | O12: =N12*I12 -> 9634079.2
A13: 12 | B13: 14000000 | C13: 1.952 | D13: 0.82 | E13: 1600 | F13: =IFERROR(B13*C13*IF(D13="", Parameters!$B$2, D13)/Parameters!$B$6, 0) -> 720464.26 | G13: =F13*IF(E13="", Parameters!$B$2, E13) -> 1.1527428e+09 | H13: =G13*Parameters!$B$4 -> 29971313 | I13: =1/POWER(1+Parameters!$B$5, A13) -> 0.31863082 | J13: =H13*I13 -> 9549784 | K13: =SUM($G$2:G13) -> 1.3832914e+10 | L13: =F13*0.95 -> 684441.04 | M13: =L13*IF(E13="",Parameters!$B$2,E13) -> 1.0951057e+09 | N13: =M13*0.0251 -> 27487152 | O13: =N13*I13 -> 8758253.8
... A34: 33 | B34: 14000000 | C34: 1.952 | D34: 0.82 | E34: 1600 | F34: =IFERROR(B34*C34*IF(D34="", Parameters!$B$2, D34)/Parameters!$B$6, 0) -> 720464.26 | G34: =F34*IF(E34="", Parameters!$B$2, E34) -> 1.1527428e+09 | H34: =G34*Parameters!$B$4 -> 29971313 | I34: =1/POWER(1+Parameters!$B$5, A34) -> 0.043056764 | J34: =H34*I34 -> 1290467.8 | K34: =SUM($G$2:G34) -> 3.8040513e+10 | L34: =F34*0.95 -> 684441.04 | M34: =L34*IF(E34="",Parameters!$B$2,E34) -> 1.0951057e+09 | N34: =M34*0.0251 -> 27487152 | O34: =N34*I34 -> 1183507.8
F39: Totals / Key Outputs | G39: =SUM(G2:G34) -> 3.8040513e+10 | H39: =SUM(H2:H34) -> 9.8905333e+08 | J39: =SUM(J2:J34) -> 2.8680845e+08 | O39: =SUM(O2:O34) -> 2.6303644e+08
F40: Total Revenue (USD) | G40: =G39 -> 3.8040513e+10
F41: Total Severance Tax (USD) | G41: =H39 -> 9.8905333e+08
F42: PV(Severance Tax) (USD) | G42: =J39 -> 2.8680845e+08

Sheet schedule_3
A1: Year | B1: Ore (t) | C1: Grade (g/t) | D1: Recovery (override, optional) | E1: Metal Price (override, optional) | F1: Metal Produced (oz) | G1: Revenue (USD) | H1: Severance Tax (USD) | I1: Discount Factor | J1: PV(Severance Tax) (USD) | K1: Cumulative Revenue (USD) | L1: Payable Metal (oz) | M1: NSR ($) | N1: Royalty ($) | O1: PV(Royalty)
A2: 1 | B2: 15000000 | C2: 1.941 | D2: 0.82 | E2: 1600 | F2: =IFERROR(B2*C2*IF(D2="", Parameters!$B$2, D2)/Parameters!$B$6, 0) -> 767576 | G2: =F2*IF(E2="", Parameters!$B$2, E2) -> 1.2281216e+09 | H2: =G2*Parameters!$B$4 -> 31931161 | I2: =1/POWER(1+Parameters!$B$5, A2) -> 0.90909091 | J2: =H2*I2 -> 29028329 | K2: =SUM($G$2:G2) -> 1.2281216e+09 | L2: =F2*0.95 -> 729197.2 | M2: =L2*IF(E2="",Parameters!$B$2,E2) -> 1.1667155e+09 | N2: =M2*0.0251 -> 29284559 | O2: =N2*I2 -> 26622327
A3: 2 | B3: 15000000 | C3: 1.941 | D3: 0.82 | E3: 1600 | F3: =IFERROR(B3*C3*IF(D3="", Parameters!$B$2, D3)/Parameters!$B$6, 0) -> 767576 | G3: =F3*IF(E3="", Parameters!$B$2, E3) -> 1.2281216e+09 | H3: =G3*Parameters!$B$4 -> 31931161 | I3: =1/POWER(1+Parameters!$B$5, A3) -> 0.82644628 | J3: =H3*I3 -> 26389390 | K3: =SUM($G$2:G3) -> 2.4562432e+09 | L3: =F3*0.95 -> 729197.2 | M3: =L3*IF(E3="",Parameters!$B$2,E3) -> 1.1667155e+09 | N3: =M3*0.0251 -> 29284559 | O3: =N3*I3 -> 24202115
A4: 3 | B4: 15000000 | C4: 1.941 | D4: 0.82 | E4: 1600 | F4: =IFERROR(B4*C4*IF(D4="", Parameters!$B$2, D4)/Parameters!$B$6, 0) -> 767576 | G4: =F4*IF(E4="", Parameters!$B$2, E4) -> 1.2281216e+09 | H4: =G4*Parameters!$B$4 -> 31931161 | I4: =1/POWER(1+Parameters!$B$5, A4) -> 0.7513148 | J4: =H4*I4 -> 23990354 | K4: =SUM($G$2:G4) -> 3.6843648e+09 | L4: =F4*0.95 -> 729197.2 | M4: =L4*IF(E4="",Parameters!$B$2,E4) -> 1.1667155e+09 | N4: =M4*0.0251 -> 29284559 | O4: =N4*I4 -> 22001923
A5: 4 | B5: 15000000 | C5: 1.941 | D5: 0.82 | E5: 1600 | F5: =IFERROR(B5*C5*IF(D5="", Parameters!$B$2, D5)/Parameters!$B$6, 0) -> 767576 | G5: =F5*IF(E5="", Parameters!$B$2, E5) -> 1.2281216e+09 | H5: =G5*Parameters!$B$4 -> 31931161 | I5: =1/POWER(1+Parameters!$B$5, A5) -> 0.68301346 | J5: =H5*I5 -> 21809413 | K5: =SUM($G$2:G5) -> 4.9124864e+09 | L5: =F5*0.95 -> 729197.2 | M5: =L5*IF(E5="",Parameters!$B$2,E5) -> 1.1667155e+09 | N5: =M5*0.0251 -> 29284559 | O5: =N5*I5 -> 20001748
A6: 5 | B6: 15000000 | C6: 1.941 | D6: 0.82 | E6: 1600 | F6: =IFERROR(B6*C6*IF(D6="", Parameters!$B$2, D6)/Parameters!$B$6, 0) -> 767576 | G6: =F6*IF(E6="", Parameters!$B$2, E6) -> 1.2281216e+09 | H6: =G6*Parameters!$B$4 -> 31931161 | I6: =1/POWER(1+Parameters!$B$5, A6) -> 0.62092132 | J6: =H6*I6 -> 19826739 | K6: =SUM($G$2:G6) -> 6.140608e+09 | L6: =F6*0.95 -> 729197.2 | M6: =L6*IF(E6="",Parameters!$B$2,E6) -> 1.1667155e+09 | N6: =M6*0.0251 -> 29284559 | O6: =N6*I6 -> 18183407
A7: 6 | B7: 15000000 | C7: 1.941 | D7: 0.82 | E7: 1600 | F7: =IFERROR(B7*C7*IF(D7="", Parameters!$B$2, D7)/Parameters!$B$6, 0) -> 767576 | G7: =F7*IF(E7="", Parameters!$B$2, E7) -> 1.2281216e+09 | H7: =G7*Parameters!$B$4 -> 31931161 | I7: =1/POWER(1+Parameters!$B$5, A7) -> 0.56447393 | J7: =H7*I7 -> 18024308 | K7: =SUM($G$2:G7) -> 7.3687296e+09 | L7: =F7*0.95 -> 729197.2 | M7: =L7*IF(E7="",Parameters!$B$2,E7) -> 1.1667155e+09 | N7: =M7*0.0251 -> 29284559 | O7: =N7*I7 -> 16530370
A8: 7 | B8: 15000000 | C8: 1.941 | D8: 0.82 | E8: 1600 | F8: =IFERROR(B8*C8*IF(D8="", Parameters!$B$2, D8)/Parameters!$B$6, 0) -> 767576 | G8: =F8*IF(E8="", Parameters!$B$2, E8) -> 1.2281216e+09 | H8: =G8*Parameters!$B$4 -> 31931161 | I8: =1/POWER(1+Parameters!$B$5, A8) -> 0.51315812 | J8: =H8*I8 -> 16385735 | K8: =SUM($G$2:G8) -> 8.5968512e+09 | L8: =F8*0.95 -> 729197.2 | M8: =L8*IF(E8="",Parameters!$B$2,E8) -> 1.1667155e+09 | N8: =M8*0.0251 -> 29284559 | O8: =N8*I8 -> 15027609
A9: 8 | B9: 15000000 | C9: 1.941 | D9: 0.82 | E9: 1600 | F9: =IFERROR(B9*C9*IF(D9="", Parameters!$B$2, D9)/Parameters!$B$6, 0) -> 767576 | G9: =F9*IF(E9="", Parameters!$B$2, E9) -> 1.2281216e+09 | H9: =G9*Parameters!$B$4 -> 31931161 | I9: =1/POWER(1+Parameters!$B$5, A9) -> 0.46650738 | J9: =H9*I9 -> 14896122 | K9: =SUM($G$2:G9) -> 9.8249728e+09 | L9: =F9*0.95 -> 729197.2 | M9: =L9*IF(E9="",Parameters!$B$2,E9) -> 1.1667155e+09 | N9: =M9*0.0251 -> 29284559 | O9: =N9*I9 -> 13661463
A10: 9 | B10: 15000000 | C10: 1.941 | D10: 0.82 | E10: 1600 | F10: =IFERROR(B10*C10*IF(D10="", Parameters!$B$2, D10)/Parameters!$B$6, 0) -> 767576 | G10: =F10*IF(E10="", Parameters!$B$2, E10) -> 1.2281216e+09 | H10: =G10*Parameters!$B$4 -> 31931161 | I10: =1/POWER(1+Parameters!$B$5, A10) -> 0.42409762 | J10: =H10*I10 -> 13541930 | K10: =SUM($G$2:G10) -> 1.1053094e+10 | L10: =F10*0.95 -> 729197.2 | M10: =L10*IF(E10="",Parameters!$B$2,E10) -> 1.1667155e+09 | N10: =M10*0.0251 -> 29284559 | O10: =N10*I10 -> 12419512
A11: 10 | B11: 15000000 | C11: 1.941 | D11: 0.82 | E11: 1600 | F11: =IFERROR(B11*C11*IF(D11="", Parameters!$B$2, D11)/Parameters!$B$6, 0) -> 767576 | G11: =F11*IF(E11="", Parameters!$B$2, E11) -> 1.2281216e+09 | H11: =G11*Parameters!$B$4 -> 31931161 | I11: =1/POWER(1+Parameters!$B$5, A11) -> 0.38554329 | J11: =H11*I11 -> 12310845 | K11: =SUM($G$2:G11) -> 1.2281216e+10 | L11: =F11*0.95 -> 729197.2 | M11: =L11*IF(E11="",Parameters!$B$2,E11) -> 1.1667155e+09 | N11: =M11*0.0251 -> 29284559 | O11: =N11*I11 -> 11290465
A12: 11 | B12: 15000000 | C12: 1.941 | D12: 0.82 | E12: 1600 | F12: =IFERROR(B12*C12*IF(D12="", Parameters!$B$2, D12)/Parameters!$B$6, 0) -> 767576 | G12: =F12*IF(E12="", Parameters!$B$2, E12) -> 1.2281216e+09 | H12: =G12*Parameters!$B$4 -> 31931161 | I12: =1/POWER(1+Parameters!$B$5, A12) -> 0.3504939 | J12: =H12*I12 -> 11191677 | K12: =SUM($G$2:G12) -> 1.3509338e+10 | L12: =F12*0.95 -> 729197.2 | M12: =L12*IF(E12="",Parameters!$B$2,E12) -> 1.1667155e+09 | N12: =M12*0.0251 -> 29284559 | O12: =N12*I12 -> 10264059
A13: 12 | B13: 15000000 | C13: 1.941 | D13: 0.82 | E13: 1600 | F13: =IFERROR(B13*C13*IF(D13="", Parameters!$B$2, D13)/Parameters!$B$6, 0) -> 767576 | G13: =F13*IF(E13="", Parameters!$B$2, E13) -> 1.2281216e+09 | H13: =G13*Parameters!$B$4 -> 31931161 | I13: =1/POWER(1+Parameters!$B$5, A13) -> 0.31863082 | J13: =H13*I13 -> 10174252 | K13: =SUM($G$2:G13) -> 1.4737459e+10 | L13: =F13*0.95 -> 729197.2 | M13: =L13*IF(E13="",Parameters!$B$2,E13) -> 1.1667155e+09 | N13: =M13*0.0251 -> 29284559 | O13: =N13*I13 -> 9330963.1
... A33: 32 | B33: 15000000 | C33: 1.941 | D33: 0.82 | E33: 1600 | F33: =IFERROR(B33*C33*IF(D33="", Parameters!$B$2, D33)/Parameters!$B$6, 0) -> 767576 | G33: =F33*IF(E33="", Parameters!$B$2, E33) -> 1.2281216e+09 | H33: =G33*Parameters!$B$4 -> 31931161 | I33: =1/POWER(1+Parameters!$B$5, A33) -> 0.047362441 | J33: =H33*I33 -> 1512337.7 | K33: =SUM($G$2:G33) -> 3.9299891e+10 | L33: =F33*0.95 -> 729197.2 | M33: =L33*IF(E33="",Parameters!$B$2,E33) -> 1.1667155e+09 | N33: =M33*0.0251 -> 29284559 | O33: =N33*I33 -> 1386988.2
F39: Totals / Key Outputs | G39: =SUM(G2:G33) -> 3.9299891e+10 | H39: =SUM(H2:H33) -> 1.0217972e+09 | J39: =SUM(J2:J33) -> 3.0418824e+08 | O39: =SUM(O2:O33) -> 2.7897571e+08
F40: Total Revenue (USD) | G40: =G39 -> 3.9299891e+10
F41: Total Severance Tax (USD) | G41: =H39 -> 1.0217972e+09
F42: PV(Severance Tax) (USD) | G42: =J39 -> 3.0418824e+08

Sheet schedule_4
A1: Year | B1: Ore (t) | C1: Grade (g/t) | D1: Recovery (override, optional) | E1: Metal Price (override, optional) | F1: Metal Produced (oz) | G1: Revenue (USD) | H1: Severance Tax (USD) | I1: Discount Factor | J1: PV(Severance Tax) (USD) | K1: Cumulative Revenue (USD) | L1: Payable Metal (oz) | M1: NSR ($) | N1: Royalty ($) | O1: PV(Royalty)
A2: 1 | B2: 16000000 | C2: 1.959 | D2: 0.82 | E2: 1600 | F2: =IFERROR(B2*C2*IF(D2="", Parameters!$B$2, D2)/Parameters!$B$6, 0) -> 826340.44 | G2: =F2*IF(E2="", Parameters!$B$2, E2) -> 1.3221447e+09 | H2: =G2*Parameters!$B$4 -> 34375762 | I2: =1/POWER(1+Parameters!$B$5, A2) -> 0.90909091 | J2: =H2*I2 -> 31250693 | K2: =SUM($G$2:G2) -> 1.3221447e+09 | L2: =F2*0.95 -> 785023.42 | M2: =L2*IF(E2="",Parameters!$B$2,E2) -> 1.2560375e+09 | N2: =M2*0.0251 -> 31526541 | O2: =N2*I2 -> 28660491
A3: 2 | B3: 16000000 | C3: 1.959 | D3: 0.82 | E3: 1600 | F3: =IFERROR(B3*C3*IF(D3="", Parameters!$B$2, D3)/Parameters!$B$6, 0) -> 826340.44 | G3: =F3*IF(E3="", Parameters!$B$2, E3) -> 1.3221447e+09 | H3: =G3*Parameters!$B$4 -> 34375762 | I3: =1/POWER(1+Parameters!$B$5, A3) -> 0.82644628 | J3: =H3*I3 -> 28409721 | K3: =SUM($G$2:G3) -> 2.6442894e+09 | L3: =F3*0.95 -> 785023.42 | M3: =L3*IF(E3="",Parameters!$B$2,E3) -> 1.2560375e+09 | N3: =M3*0.0251 -> 31526541 | O3: =N3*I3 -> 26054992
A4: 3 | B4: 16000000 | C4: 1.959 | D4: 0.82 | E4: 1600 | F4: =IFERROR(B4*C4*IF(D4="", Parameters!$B$2, D4)/Parameters!$B$6, 0) -> 826340.44 | G4: =F4*IF(E4="", Parameters!$B$2, E4) -> 1.3221447e+09 | H4: =G4*Parameters!$B$4 -> 34375762 | I4: =1/POWER(1+Parameters!$B$5, A4) -> 0.7513148 | J4: =H4*I4 -> 25827019 | K4: =SUM($G$2:G4) -> 3.9664341e+09 | L4: =F4*0.95 -> 785023.42 | M4: =L4*IF(E4="",Parameters!$B$2,E4) -> 1.2560375e+09 | N4: =M4*0.0251 -> 31526541 | O4: =N4*I4 -> 23686357
A5: 4 | B5: 16000000 | C5: 1.959 | D5: 0.82 | E5: 1600 | F5: =IFERROR(B5*C5*IF(D5="", Parameters!$B$2, D5)/Parameters!$B$6, 0) -> 826340.44 | G5: =F5*IF(E5="", Parameters!$B$2, E5) -> 1.3221447e+09 | H5: =G5*Parameters!$B$4 -> 34375762 | I5: =1/POWER(1+Parameters!$B$5, A5) -> 0.68301346 | J5: =H5*I5 -> 23479108 | K5: =SUM($G$2:G5) -> 5.2885788e+09 | L5: =F5*0.95 -> 785023.42 | M5: =L5*IF(E5="",Parameters!$B$2,E5) -> 1.2560375e+09 | N5: =M5*0.0251 -> 31526541 | O5: =N5*I5 -> 21533051
A6: 5 | B6: 16000000 | C6: 1.959 | D6: 0.82 | E6: 1600 | F6: =IFERROR(B6*C6*IF(D6="", Parameters!$B$2, D6)/Parameters!$B$6, 0) -> 826340.44 | G6: =F6*IF(E6="", Parameters!$B$2, E6) -> 1.3221447e+09 | H6: =G6*Parameters!$B$4 -> 34375762 | I6: =1/POWER(1+Parameters!$B$5, A6) -> 0.62092132 | J6: =H6*I6 -> 21344644 | K6: =SUM($G$2:G6) -> 6.6107236e+09 | L6: =F6*0.95 -> 785023.42 | M6: =L6*IF(E6="",Parameters!$B$2,E6) -> 1.2560375e+09 | N6: =M6*0.0251 -> 31526541 | O6: =N6*I6 -> 19575501
A7: 6 | B7: 16000000 | C7: 1.959 | D7: 0.82 | E7: 1600 | F7: =IFERROR(B7*C7*IF(D7="", Parameters!$B$2, D7)/Parameters!$B$6, 0) -> 826340.44 | G7: =F7*IF(E7="", Parameters!$B$2, E7) -> 1.3221447e+09 | H7: =G7*Parameters!$B$4 -> 34375762 | I7: =1/POWER(1+Parameters!$B$5, A7) -> 0.56447393 | J7: =H7*I7 -> 19404222 | K7: =SUM($G$2:G7) -> 7.9328683e+09 | L7: =F7*0.95 -> 785023.42 | M7: =L7*IF(E7="",Parameters!$B$2,E7) -> 1.2560375e+09 | N7: =M7*0.0251 -> 31526541 | O7: =N7*I7 -> 17795910
A8: 7 | B8: 16000000 | C8: 1.959 | D8: 0.82 | E8: 1600 | F8: =IFERROR(B8*C8*IF(D8="", Parameters!$B$2, D8)/Parameters!$B$6, 0) -> 826340.44 | G8: =F8*IF(E8="", Parameters!$B$2, E8) -> 1.3221447e+09 | H8: =G8*Parameters!$B$4 -> 34375762 | I8: =1/POWER(1+Parameters!$B$5, A8) -> 0.51315812 | J8: =H8*I8 -> 17640202 | K8: =SUM($G$2:G8) -> 9.255013e+09 | L8: =F8*0.95 -> 785023.42 | M8: =L8*IF(E8="",Parameters!$B$2,E8) -> 1.2560375e+09 | N8: =M8*0.0251 -> 31526541 | O8: =N8*I8 -> 16178100
A9: 8 | B9: 16000000 | C9: 1.959 | D9: 0.82 | E9: 1600 | F9: =IFERROR(B9*C9*IF(D9="", Parameters!$B$2, D9)/Parameters!$B$6, 0) -> 826340.44 | G9: =F9*IF(E9="", Parameters!$B$2, E9) -> 1.3221447e+09 | H9: =G9*Parameters!$B$4 -> 34375762 | I9: =1/POWER(1+Parameters!$B$5, A9) -> 0.46650738 | J9: =H9*I9 -> 16036547 | K9: =SUM($G$2:G9) -> 1.0577158e+10 | L9: =F9*0.95 -> 785023.42 | M9: =L9*IF(E9="",Parameters!$B$2,E9) -> 1.2560375e+09 | N9: =M9*0.0251 -> 31526541 | O9: =N9*I9 -> 14707364
A10: 9 | B10: 16000000 | C10: 1.959 | D10: 0.82 | E10: 1600 | F10: =IFERROR(B10*C10*IF(D10="", Parameters!$B$2, D10)/Parameters!$B$6, 0) -> 826340.44 | G10: =F10*IF(E10="", Parameters!$B$2, E10) -> 1.3221447e+09 | H10: =G10*Parameters!$B$4 -> 34375762 | I10: =1/POWER(1+Parameters!$B$5, A10) -> 0.42409762 | J10: =H10*I10 -> 14578679 | K10: =SUM($G$2:G10) -> 1.1899302e+10 | L10: =F10*0.95 -> 785023.42 | M10: =L10*IF(E10="",Parameters!$B$2,E10) -> 1.2560375e+09 | N10: =M10*0.0251 -> 31526541 | O10: =N10*I10 -> 13370331
A11: 10 | B11: 16000000 | C11: 1.959 | D11: 0.82 | E11: 1600 | F11: =IFERROR(B11*C11*IF(D11="", Parameters!$B$2, D11)/Parameters!$B$6, 0) -> 826340.44 | G11: =F11*IF(E11="", Parameters!$B$2, E11) -> 1.3221447e+09 | H11: =G11*Parameters!$B$4 -> 34375762 | I11: =1/POWER(1+Parameters!$B$5, A11) -> 0.38554329 | J11: =H11*I11 -> 13253345 | K11: =SUM($G$2:G11) -> 1.3221447e+10 | L11: =F11*0.95 -> 785023.42 | M11: =L11*IF(E11="",Parameters!$B$2,E11) -> 1.2560375e+09 | N11: =M11*0.0251 -> 31526541 | O11: =N11*I11 -> 12154846
A12: 11 | B12: 16000000 | C12: 1.959 | D12: 0.82 | E12: 1600 | F12: =IFERROR(B12*C12*IF(D12="", Parameters!$B$2, D12)/Parameters!$B$6, 0) -> 826340.44 | G12: =F12*IF(E12="", Parameters!$B$2, E12) -> 1.3221447e+09 | H12: =G12*Parameters!$B$4 -> 34375762 | I12: =1/POWER(1+Parameters!$B$5, A12) -> 0.3504939 | J12: =H12*I12 -> 12048495 | K12: =SUM($G$2:G12) -> 1.4543592e+10 | L12: =F12*0.95 -> 785023.42 | M12: =L12*IF(E12="",Parameters!$B$2,E12) -> 1.2560375e+09 | N12: =M12*0.0251 -> 31526541 | O12: =N12*I12 -> 11049860
A13: 12 | B13: 16000000 | C13: 1.959 | D13: 0.82 | E13: 1600 | F13: =IFERROR(B13*C13*IF(D13="", Parameters!$B$2, D13)/Parameters!$B$6, 0) -> 826340.44 | G13: =F13*IF(E13="", Parameters!$B$2, E13) -> 1.3221447e+09 | H13: =G13*Parameters!$B$4 -> 34375762 | I13: =1/POWER(1+Parameters!$B$5, A13) -> 0.31863082 | J13: =H13*I13 -> 10953177 | K13: =SUM($G$2:G13) -> 1.5865737e+10 | L13: =F13*0.95 -> 785023.42 | M13: =L13*IF(E13="",Parameters!$B$2,E13) -> 1.2560375e+09 | N13: =M13*0.0251 -> 31526541 | O13: =N13*I13 -> 10045327
... A30: 29 | B30: 16000000 | C30: 1.959 | D30: 0.82 | E30: 1600 | F30: =IFERROR(B30*C30*IF(D30="", Parameters!$B$2, D30)/Parameters!$B$6, 0) -> 826340.44 | G30: =F30*IF(E30="", Parameters!$B$2, E30) -> 1.3221447e+09 | H30: =G30*Parameters!$B$4 -> 34375762 | I30: =1/POWER(1+Parameters!$B$5, A30) -> 0.063039409 | J30: =H30*I30 -> 2167027.7 | K30: =SUM($G$2:G30) -> 3.8342197e+10 | L30: =F30*0.95 -> 785023.42 | M30: =L30*IF(E30="",Parameters!$B$2,E30) -> 1.2560375e+09 | N30: =M30*0.0251 -> 31526541 | O30: =N30*I30 -> 1987414.5
F39: Totals / Key Outputs | G39: =SUM(G2:G33) -> 3.8342197e+10 | H39: =SUM(H2:H33) -> 9.9689711e+08 | J39: =SUM(J2:J30) -> 3.2208735e+08 | O39: =SUM(O2:O30) -> 2.9539126e+08
F40: Total Revenue (USD) | G40: =G39 -> 3.8342197e+10
F41: Total Severance Tax (USD) | G41: =H39 -> 9.9689711e+08
F42: PV(Severance Tax) (USD) | G42: =J39 -> 3.2208735e+08

Sheet schedule_5
A1: Year | B1: Ore (t) | C1: Grade (g/t) | D1: Recovery (override, optional) | E1: Metal Price (override, optional) | F1: Metal Produced (oz) | G1: Revenue (USD) | H1: Severance Tax (USD) | I1: Discount Factor | J1: PV(Severance Tax) (USD) | K1: Cumulative Revenue (USD) | L1: Payable Metal (oz) | M1: NSR ($) | N1: Royalty ($) | O1: PV(Royalty)
A2: 1 | B2: 17000000 | C2: 2.02 | D2: 0.82 | E2: 1600 | F2: =IFERROR(B2*C2*IF(D2="", Parameters!$B$2, D2)/Parameters!$B$6, 0) -> 905325.77 | G2: =F2*IF(E2="", Parameters!$B$2, E2) -> 1.4485212e+09 | H2: =G2*Parameters!$B$4 -> 37661552 | I2: =1/POWER(1+Parameters!$B$5, A2) -> 0.90909091 | J2: =H2*I2 -> 34237774 | K2: =SUM($G$2:G2) -> 1.4485212e+09 | L2: =F2*0.95 -> 860059.48 | M2: =L2*IF(E2="",Parameters!$B$2,E2) -> 1.3760952e+09 | N2: =M2*0.0251 -> 34539989 | O2: =N2*I2 -> 31399990
A3: 2 | B3: 17000000 | C3: 2.02 | D3: 0.82 | E3: 1600 | F3: =IFERROR(B3*C3*IF(D3="", Parameters!$B$2, D3)/Parameters!$B$6, 0) -> 905325.77 | G3: =F3*IF(E3="", Parameters!$B$2, E3) -> 1.4485212e+09 | H3: =G3*Parameters!$B$4 -> 37661552 | I3: =1/POWER(1+Parameters!$B$5, A3) -> 0.82644628 | J3: =H3*I3 -> 31125250 | K3: =SUM($G$2:G3) -> 2.8970425e+09 | L3: =F3*0.95 -> 860059.48 | M3: =L3*IF(E3="",Parameters!$B$2,E3) -> 1.3760952e+09 | N3: =M3*0.0251 -> 34539989 | O3: =N3*I3 -> 28545445
A4: 3 | B4: 17000000 | C4: 2.02 | D4: 0.82 | E4: 1600 | F4: =IFERROR(B4*C4*IF(D4="", Parameters!$B$2, D4)/Parameters!$B$6, 0) -> 905325.77 | G4: =F4*IF(E4="", Parameters!$B$2, E4) -> 1.4485212e+09 | H4: =G4*Parameters!$B$4 -> 37661552 | I4: =1/POWER(1+Parameters!$B$5, A4) -> 0.7513148 | J4: =H4*I4 -> 28295681 | K4: =SUM($G$2:G4) -> 4.3455637e+09 | L4: =F4*0.95 -> 860059.48 | M4: =L4*IF(E4="",Parameters!$B$2,E4) -> 1.3760952e+09 | N4: =M4*0.0251 -> 34539989 | O4: =N4*I4 -> 25950405
A5: 4 | B5: 17000000 | C5: 2.02 | D5: 0.82 | E5: 1600 | F5: =IFERROR(B5*C5*IF(D5="", Parameters!$B$2, D5)/Parameters!$B$6, 0) -> 905325.77 | G5: =F5*IF(E5="", Parameters!$B$2, E5) -> 1.4485212e+09 | H5: =G5*Parameters!$B$4 -> 37661552 | I5: =1/POWER(1+Parameters!$B$5, A5) -> 0.68301346 | J5: =H5*I5 -> 25723347 | K5: =SUM($G$2:G5) -> 5.7940849e+09 | L5: =F5*0.95 -> 860059.48 | M5: =L5*IF(E5="",Parameters!$B$2,E5) -> 1.3760952e+09 | N5: =M5*0.0251 -> 34539989 | O5: =N5*I5 -> 23591277
A6: 5 | B6: 17000000 | C6: 2.02 | D6: 0.82 | E6: 1600 | F6: =IFERROR(B6*C6*IF(D6="", Parameters!$B$2, D6)/Parameters!$B$6, 0) -> 905325.77 | G6: =F6*IF(E6="", Parameters!$B$2, E6) -> 1.4485212e+09 | H6: =G6*Parameters!$B$4 -> 37661552 | I6: =1/POWER(1+Parameters!$B$5, A6) -> 0.62092132 | J6: =H6*I6 -> 23384861 | K6: =SUM($G$2:G6) -> 7.2426061e+09 | L6: =F6*0.95 -> 860059.48 | M6: =L6*IF(E6="",Parameters!$B$2,E6) -> 1.3760952e+09 | N6: =M6*0.0251 -> 34539989 | O6: =N6*I6 -> 21446615
A7: 6 | B7: 17000000 | C7: 2.02 | D7: 0.82 | E7: 1600 | F7: =IFERROR(B7*C7*IF(D7="", Parameters!$B$2, D7)/Parameters!$B$6, 0) -> 905325.77 | G7: =F7*IF(E7="", Parameters!$B$2, E7) -> 1.4485212e+09 | H7: =G7*Parameters!$B$4 -> 37661552 | I7: =1/POWER(1+Parameters!$B$5, A7) -> 0.56447393 | J7: =H7*I7 -> 21258964 | K7: =SUM($G$2:G7) -> 8.6911274e+09 | L7: =F7*0.95 -> 860059.48 | M7: =L7*IF(E7="",Parameters!$B$2,E7) -> 1.3760952e+09 | N7: =M7*0.0251 -> 34539989 | O7: =N7*I7 -> 19496923
A8: 7 | B8: 17000000 | C8: 2.02 | D8: 0.82 | E8: 1600 | F8: =IFERROR(B8*C8*IF(D8="", Parameters!$B$2, D8)/Parameters!$B$6, 0) -> 905325.77 | G8: =F8*IF(E8="", Parameters!$B$2, E8) -> 1.4485212e+09 | H8: =G8*Parameters!$B$4 -> 37661552 | I8: =1/POWER(1+Parameters!$B$5, A8) -> 0.51315812 | J8: =H8*I8 -> 19326331 | K8: =SUM($G$2:G8) -> 1.0139649e+10 | L8: =F8*0.95 -> 860059.48 | M8: =L8*IF(E8="",Parameters!$B$2,E8) -> 1.3760952e+09 | N8: =M8*0.0251 -> 34539989 | O8: =N8*I8 -> 17724476
A9: 8 | B9: 17000000 | C9: 2.02 | D9: 0.82 | E9: 1600 | F9: =IFERROR(B9*C9*IF(D9="", Parameters!$B$2, D9)/Parameters!$B$6, 0) -> 905325.77 | G9: =F9*IF(E9="", Parameters!$B$2, E9) -> 1.4485212e+09 | H9: =G9*Parameters!$B$4 -> 37661552 | I9: =1/POWER(1+Parameters!$B$5, A9) -> 0.46650738 | J9: =H9*I9 -> 17569392 | K9: =SUM($G$2:G9) -> 1.158817e+10 | L9: =F9*0.95 -> 860059.48 | M9: =L9*IF(E9="",Parameters!$B$2,E9) -> 1.3760952e+09 | N9: =M9*0.0251 -> 34539989 | O9: =N9*I9 -> 16113160
A10: 9 | B10: 17000000 | C10: 2.02 | D10: 0.82 | E10: 1600 | F10: =IFERROR(B10*C10*IF(D10="", Parameters!$B$2, D10)/Parameters!$B$6, 0) -> 905325.77 | G10: =F10*IF(E10="", Parameters!$B$2, E10) -> 1.4485212e+09 | H10: =G10*Parameters!$B$4 -> 37661552 | I10: =1/POWER(1+Parameters!$B$5, A10) -> 0.42409762 | J10: =H10*I10 -> 15972174 | K10: =SUM($G$2:G10) -> 1.3036691e+10 | L10: =F10*0.95 -> 860059.48 | M10: =L10*IF(E10="",Parameters!$B$2,E10) -> 1.3760952e+09 | N10: =M10*0.0251 -> 34539989 | O10: =N10*I10 -> 14648327
A11: 10 | B11: 17000000 | C11: 2.02 | D11: 0.82 | E11: 1600 | F11: =IFERROR(B11*C11*IF(D11="", Parameters!$B$2, D11)/Parameters!$B$6, 0) -> 905325.77 | G11: =F11*IF(E11="", Parameters!$B$2, E11) -> 1.4485212e+09 | H11: =G11*Parameters!$B$4 -> 37661552 | I11: =1/POWER(1+Parameters!$B$5, A11) -> 0.38554329 | J11: =H11*I11 -> 14520159 | K11: =SUM($G$2:G11) -> 1.4485212e+10 | L11: =F11*0.95 -> 860059.48 | M11: =L11*IF(E11="",Parameters!$B$2,E11) -> 1.3760952e+09 | N11: =M11*0.0251 -> 34539989 | O11: =N11*I11 -> 13316661
A12: 11 | B12: 17000000 | C12: 2.02 | D12: 0.82 | E12: 1600 | F12: =IFERROR(B12*C12*IF(D12="", Parameters!$B$2, D12)/Parameters!$B$6, 0) -> 905325.77 | G12: =F12*IF(E12="", Parameters!$B$2, E12) -> 1.4485212e+09 | H12: =G12*Parameters!$B$4 -> 37661552 | I12: =1/POWER(1+Parameters!$B$5, A12) -> 0.3504939 | J12: =H12*I12 -> 13200144 | K12: =SUM($G$2:G12) -> 1.5933734e+10 | L12: =F12*0.95 -> 860059.48 | M12: =L12*IF(E12="",Parameters!$B$2,E12) -> 1.3760952e+09 | N12: =M12*0.0251 -> 34539989 | O12: =N12*I12 -> 12106055
A13: 12 | B13: 17000000 | C13: 2.02 | D13: 0.82 | E13: 1600 | F13: =IFERROR(B13*C13*IF(D13="", Parameters!$B$2, D13)/Parameters!$B$6, 0) -> 905325.77 | G13: =F13*IF(E13="", Parameters!$B$2, E13) -> 1.4485212e+09 | H13: =G13*Parameters!$B$4 -> 37661552 | I13: =1/POWER(1+Parameters!$B$5, A13) -> 0.31863082 | J13: =H13*I13 -> 12000131 | K13: =SUM($G$2:G13) -> 1.7382255e+10 | L13: =F13*0.95 -> 860059.48 | M13: =L13*IF(E13="",Parameters!$B$2,E13) -> 1.3760952e+09 | N13: =M13*0.0251 -> 34539989 | O13: =N13*I13 -> 11005505
... A26: 25 | B26: 17000000 | C26: 2.02 | D26: 0.82 | E26: 1600 | F26: =IFERROR(B26*C26*IF(D26="", Parameters!$B$2, D26)/Parameters!$B$6, 0) -> 905325.77 | G26: =F26*IF(E26="", Parameters!$B$2, E26) -> 1.4485212e+09 | H26: =G26*Parameters!$B$4 -> 37661552 | I26: =1/POWER(1+Parameters!$B$5, A26) -> 0.092295998 | J26: =H26*I26 -> 3476010.5 | K26: =SUM($G$2:G26) -> 3.6213031e+10 | L26: =F26*0.95 -> 860059.48 | M26: =L26*IF(E26="",Parameters!$B$2,E26) -> 1.3760952e+09 | N26: =M26*0.0251 -> 34539989 | O26: =N26*I26 -> 3187902.7
F39: Totals / Key Outputs | G39: =SUM(G2:G33) -> 3.6213031e+10 | H39: =SUM(H2:H33) -> 9.415388e+08 | J39: =SUM(J2:J26) -> 3.4185541e+08 | O39: =SUM(O2:O26) -> 3.1352086e+08
F40: Total Revenue (USD) | G40: =G39 -> 3.6213031e+10
F41: Total Severance Tax (USD) | G41: =H39 -> 9.415388e+08
F42: PV(Severance Tax) (USD) | G42: =J39 -> 3.4185541e+08

Sheet schedule_6
A1: Year | B1: Ore (t) | C1: Grade (g/t) | D1: Recovery (override, optional) | E1: Metal Price (override, optional) | F1: Metal Produced (oz) | G1: Revenue (USD) | H1: Severance Tax (USD) | I1: Discount Factor | J1: PV(Severance Tax) (USD) | K1: Cumulative Revenue (USD) | L1: Payable Metal (oz) | M1: NSR ($) | N1: Royalty ($) | O1: PV(Royalty)
A2: 1 | B2: 18000000 | C2: 1.995 | D2: 0.82 | E2: 1600 | F2: =IFERROR(B2*C2*IF(D2="", Parameters!$B$2, D2)/Parameters!$B$6, 0) -> 946716.61 | G2: =F2*IF(E2="", Parameters!$B$2, E2) -> 1.5147466e+09 | H2: =G2*Parameters!$B$4 -> 39383411 | I2: =1/POWER(1+Parameters!$B$5, A2) -> 0.90909091 | J2: =H2*I2 -> 35803101 | K2: =SUM($G$2:G2) -> 1.5147466e+09 | L2: =F2*0.95 -> 899380.78 | M2: =L2*IF(E2="",Parameters!$B$2,E2) -> 1.4390092e+09 | N2: =M2*0.0251 -> 36119132 | O2: =N2*I2 -> 32835575
A3: 2 | B3: 18000000 | C3: 1.995 | D3: 0.82 | E3: 1600 | F3: =IFERROR(B3*C3*IF(D3="", Parameters!$B$2, D3)/Parameters!$B$6, 0) -> 946716.61 | G3: =F3*IF(E3="", Parameters!$B$2, E3) -> 1.5147466e+09 | H3: =G3*Parameters!$B$4 -> 39383411 | I3: =1/POWER(1+Parameters!$B$5, A3) -> 0.82644628 | J3: =H3*I3 -> 32548273 | K3: =SUM($G$2:G3) -> 3.0294931e+09 | L3: =F3*0.95 -> 899380.78 | M3: =L3*IF(E3="",Parameters!$B$2,E3) -> 1.4390092e+09 | N3: =M3*0.0251 -> 36119132 | O3: =N3*I3 -> 29850522
A4: 3 | B4: 18000000 | C4: 1.995 | D4: 0.82 | E4: 1600 | F4: =IFERROR(B4*C4*IF(D4="", Parameters!$B$2, D4)/Parameters!$B$6, 0) -> 946716.61 | G4: =F4*IF(E4="", Parameters!$B$2, E4) -> 1.5147466e+09 | H4: =G4*Parameters!$B$4 -> 39383411 | I4: =1/POWER(1+Parameters!$B$5, A4) -> 0.7513148 | J4: =H4*I4 -> 29589339 | K4: =SUM($G$2:G4) -> 4.5442397e+09 | L4: =F4*0.95 -> 899380.78 | M4: =L4*IF(E4="",Parameters!$B$2,E4) -> 1.4390092e+09 | N4: =M4*0.0251 -> 36119132 | O4: =N4*I4 -> 27136838
A5: 4 | B5: 18000000 | C5: 1.995 | D5: 0.82 | E5: 1600 | F5: =IFERROR(B5*C5*IF(D5="", Parameters!$B$2, D5)/Parameters!$B$6, 0) -> 946716.61 | G5: =F5*IF(E5="", Parameters!$B$2, E5) -> 1.5147466e+09 | H5: =G5*Parameters!$B$4 -> 39383411 | I5: =1/POWER(1+Parameters!$B$5, A5) -> 0.68301346 | J5: =H5*I5 -> 26899400 | K5: =SUM($G$2:G5) -> 6.0589863e+09 | L5: =F5*0.95 -> 899380.78 | M5: =L5*IF(E5="",Parameters!$B$2,E5) -> 1.4390092e+09 | N5: =M5*0.0251 -> 36119132 | O5: =N5*I5 -> 24669853
A6: 5 | B6: 18000000 | C6: 1.995 | D6: 0.82 | E6: 1600 | F6: =IFERROR(B6*C6*IF(D6="", Parameters!$B$2, D6)/Parameters!$B$6, 0) -> 946716.61 | G6: =F6*IF(E6="", Parameters!$B$2, E6) -> 1.5147466e+09 | H6: =G6*Parameters!$B$4 -> 39383411 | I6: =1/POWER(1+Parameters!$B$5, A6) -> 0.62092132 | J6: =H6*I6 -> 24454000 | K6: =SUM($G$2:G6) -> 7.5737329e+09 | L6: =F6*0.95 -> 899380.78 | M6: =L6*IF(E6="",Parameters!$B$2,E6) -> 1.4390092e+09 | N6: =M6*0.0251 -> 36119132 | O6: =N6*I6 -> 22427139
A7: 6 | B7: 18000000 | C7: 1.995 | D7: 0.82 | E7: 1600 | F7: =IFERROR(B7*C7*IF(D7="", Parameters!$B$2, D7)/Parameters!$B$6, 0) -> 946716.61 | G7: =F7*IF(E7="", Parameters!$B$2, E7) -> 1.5147466e+09 | H7: =G7*Parameters!$B$4 -> 39383411 | I7: =1/POWER(1+Parameters!$B$5, A7) -> 0.56447393 | J7: =H7*I7 -> 22230909 | K7: =SUM($G$2:G7) -> 9.0884794e+09 | L7: =F7*0.95 -> 899380.78 | M7: =L7*IF(E7="",Parameters!$B$2,E7) -> 1.4390092e+09 | N7: =M7*0.0251 -> 36119132 | O7: =N7*I7 -> 20388308
A8: 7 | B8: 18000000 | C8: 1.995 | D8: 0.82 | E8: 1600 | F8: =IFERROR(B8*C8*IF(D8="", Parameters!$B$2, D8)/Parameters!$B$6, 0) -> 946716.61 | G8: =F8*IF(E8="", Parameters!$B$2, E8) -> 1.5147466e+09 | H8: =G8*Parameters!$B$4 -> 39383411 | I8: =1/POWER(1+Parameters!$B$5, A8) -> 0.51315812 | J8: =H8*I8 -> 20209917 | K8: =SUM($G$2:G8) -> 1.0603226e+10 | L8: =F8*0.95 -> 899380.78 | M8: =L8*IF(E8="",Parameters!$B$2,E8) -> 1.4390092e+09 | N8: =M8*0.0251 -> 36119132 | O8: =N8*I8 -> 18534826
A9: 8 | B9: 18000000 | C9: 1.995 | D9: 0.82 | E9: 1600 | F9: =IFERROR(B9*C9*IF(D9="", Parameters!$B$2, D9)/Parameters!$B$6, 0) -> 946716.61 | G9: =F9*IF(E9="", Parameters!$B$2, E9) -> 1.5147466e+09 | H9: =G9*Parameters!$B$4 -> 39383411 | I9: =1/POWER(1+Parameters!$B$5, A9) -> 0.46650738 | J9: =H9*I9 -> 18372652 | K9: =SUM($G$2:G9) -> 1.2117973e+10 | L9: =F9*0.95 -> 899380.78 | M9: =L9*IF(E9="",Parameters!$B$2,E9) -> 1.4390092e+09 | N9: =M9*0.0251 -> 36119132 | O9: =N9*I9 -> 16849842
A10: 9 | B10: 18000000 | C10: 1.995 | D10: 0.82 | E10: 1600 | F10: =IFERROR(B10*C10*IF(D10="", Parameters!$B$2, D10)/Parameters!$B$6, 0) -> 946716.61 | G10: =F10*IF(E10="", Parameters!$B$2, E10) -> 1.5147466e+09 | H10: =G10*Parameters!$B$4 -> 39383411 | I10: =1/POWER(1+Parameters!$B$5, A10) -> 0.42409762 | J10: =H10*I10 -> 16702411 | K10: =SUM($G$2:G10) -> 1.3632719e+10 | L10: =F10*0.95 -> 899380.78 | M10: =L10*IF(E10="",Parameters!$B$2,E10) -> 1.4390092e+09 | N10: =M10*0.0251 -> 36119132 | O10: =N10*I10 -> 15318038
A11: 10 | B11: 18000000 | C11: 1.995 | D11: 0.82 | E11: 1600 | F11: =IFERROR(B11*C11*IF(D11="", Parameters!$B$2, D11)/Parameters!$B$6, 0) -> 946716.61 | G11: =F11*IF(E11="", Parameters!$B$2, E11) -> 1.5147466e+09 | H11: =G11*Parameters!$B$4 -> 39383411 | I11: =1/POWER(1+Parameters!$B$5, A11) -> 0.38554329 | J11: =H11*I11 -> 15184010 | K11: =SUM($G$2:G11) -> 1.5147466e+10 | L11: =F11*0.95 -> 899380.78 | M11: =L11*IF(E11="",Parameters!$B$2,E11) -> 1.4390092e+09 | N11: =M11*0.0251 -> 36119132 | O11: =N11*I11 -> 13925489
A12: 11 | B12: 18000000 | C12: 1.995 | D12: 0.82 | E12: 1600 | F12: =IFERROR(B12*C12*IF(D12="", Parameters!$B$2, D12)/Parameters!$B$6, 0) -> 946716.61 | G12: =F12*IF(E12="", Parameters!$B$2, E12) -> 1.5147466e+09 | H12: =G12*Parameters!$B$4 -> 39383411 | I12: =1/POWER(1+Parameters!$B$5, A12) -> 0.3504939 | J12: =H12*I12 -> 13803645 | K12: =SUM($G$2:G12) -> 1.6662212e+10 | L12: =F12*0.95 -> 899380.78 | M12: =L12*IF(E12="",Parameters!$B$2,E12) -> 1.4390092e+09 | N12: =M12*0.0251 -> 36119132 | O12: =N12*I12 -> 12659535
A13: 12 | B13: 18000000 | C13: 1.995 | D13: 0.82 | E13: 1600 | F13: =IFERROR(B13*C13*IF(D13="", Parameters!$B$2, D13)/Parameters!$B$6, 0) -> 946716.61 | G13: =F13*IF(E13="", Parameters!$B$2, E13) -> 1.5147466e+09 | H13: =G13*Parameters!$B$4 -> 39383411 | I13: =1/POWER(1+Parameters!$B$5, A13) -> 0.31863082 | J13: =H13*I13 -> 12548768 | K13: =SUM($G$2:G13) -> 1.8176959e+10 | L13: =F13*0.95 -> 899380.78 | M13: =L13*IF(E13="",Parameters!$B$2,E13) -> 1.4390092e+09 | N13: =M13*0.0251 -> 36119132 | O13: =N13*I13 -> 11508669
... A28: 27 | B28: 18000000 | C28: 1.995 | D28: 0.82 | E28: 1600 | F28: =IFERROR(B28*C28*IF(D28="", Parameters!$B$2, D28)/Parameters!$B$6, 0) -> 946716.61 | G28: =F28*IF(E28="", Parameters!$B$2, E28) -> 1.5147466e+09 | H28: =G28*Parameters!$B$4 -> 39383411 | I28: =1/POWER(1+Parameters!$B$5, A28) -> 0.076277684 | J28: =H28*I28 -> 3004075.4 | K28: =SUM($G$2:G28) -> 4.0898157e+10 | L28: =F28*0.95 -> 899380.78 | M28: =L28*IF(E28="",Parameters!$B$2,E28) -> 1.4390092e+09 | N28: =M28*0.0251 -> 36119132 | O28: =N28*I28 -> 2755083.8
F39: Totals / Key Outputs | G39: =SUM(G2:G33) -> 4.0898157e+10 | H39: =SUM(H2:H33) -> 1.0633521e+09 | J39: =SUM(J2:J28) -> 3.6379335e+08 | O39: =SUM(O2:O28) -> 3.3364048e+08
F40: Total Revenue (USD) | G40: =G39 -> 4.0898157e+10
F41: Total Severance Tax (USD) | G41: =H39 -> 1.0633521e+09
F42: PV(Severance Tax) (USD) | G42: =J39 -> 3.6379335e+08

Sheet schedule_7
A1: Year | B1: Ore (t) | C1: Grade (g/t) | D1: Recovery (override, optional) | E1: Metal Price (override, optional) | F1: Metal Produced (oz) | G1: Revenue (USD) | H1: Severance Tax (USD) | I1: Discount Factor | J1: PV(Severance Tax) (USD) | K1: Cumulative Revenue (USD) | L1: Payable Metal (oz) | M1: NSR ($) | N1: Royalty ($) | O1: PV(Royalty)
A2: 1 | B2: 19000000 | C2: 1.929 | D2: 0.82 | E2: 1600 | F2: =IFERROR(B2*C2*IF(D2="", Parameters!$B$2, D2)/Parameters!$B$6, 0) -> 966252.03 | G2: =F2*IF(E2="", Parameters!$B$2, E2) -> 1.5460032e+09 | H2: =G2*Parameters!$B$4 -> 40196084 | I2: =1/POWER(1+Parameters!$B$5, A2) -> 0.90909091 | J2: =H2*I2 -> 36541895 | K2: =SUM($G$2:G2) -> 1.5460032e+09 | L2: =F2*0.95 -> 917939.43 | M2: =L2*IF(E2="",Parameters!$B$2,E2) -> 1.4687031e+09 | N2: =M2*0.0251 -> 36864447 | O2: =N2*I2 -> 33513134
A3: 2 | B3: 19000000 | C3: 1.929 | D3: 0.82 | E3: 1600 | F3: =IFERROR(B3*C3*IF(D3="", Parameters!$B$2, D3)/Parameters!$B$6, 0) -> 966252.03 | G3: =F3*IF(E3="", Parameters!$B$2, E3) -> 1.5460032e+09 | H3: =G3*Parameters!$B$4 -> 40196084 | I3: =1/POWER(1+Parameters!$B$5, A3) -> 0.82644628 | J3: =H3*I3 -> 33219904 | K3: =SUM($G$2:G3) -> 3.0920065e+09 | L3: =F3*0.95 -> 917939.43 | M3: =L3*IF(E3="",Parameters!$B$2,E3) -> 1.4687031e+09 | N3: =M3*0.0251 -> 36864447 | O3: =N3*I3 -> 30466485
A4: 3 | B4: 19000000 | C4: 1.929 | D4: 0.82 | E4: 1600 | F4: =IFERROR(B4*C4*IF(D4="", Parameters!$B$2, D4)/Parameters!$B$6, 0) -> 966252.03 | G4: =F4*IF(E4="", Parameters!$B$2, E4) -> 1.5460032e+09 | H4: =G4*Parameters!$B$4 -> 40196084 | I4: =1/POWER(1+Parameters!$B$5, A4) -> 0.7513148 | J4: =H4*I4 -> 30199913 | K4: =SUM($G$2:G4) -> 4.6380097e+09 | L4: =F4*0.95 -> 917939.43 | M4: =L4*IF(E4="",Parameters!$B$2,E4) -> 1.4687031e+09 | N4: =M4*0.0251 -> 36864447 | O4: =N4*I4 -> 27696805
A5: 4 | B5: 19000000 | C5: 1.929 | D5: 0.82 | E5: 1600 | F5: =IFERROR(B5*C5*IF(D5="", Parameters!$B$2, D5)/Parameters!$B$6, 0) -> 966252.03 | G5: =F5*IF(E5="", Parameters!$B$2, E5) -> 1.5460032e+09 | H5: =G5*Parameters!$B$4 -> 40196084 | I5: =1/POWER(1+Parameters!$B$5, A5) -> 0.68301346 | J5: =H5*I5 -> 27454467 | K5: =SUM($G$2:G5) -> 6.184013e+09 | L5: =F5*0.95 -> 917939.43 | M5: =L5*IF(E5="",Parameters!$B$2,E5) -> 1.4687031e+09 | N5: =M5*0.0251 -> 36864447 | O5: =N5*I5 -> 25178914
A6: 5 | B6: 19000000 | C6: 1.929 | D6: 0.82 | E6: 1600 | F6: =IFERROR(B6*C6*IF(D6="", Parameters!$B$2, D6)/Parameters!$B$6, 0) -> 966252.03 | G6: =F6*IF(E6="", Parameters!$B$2, E6) -> 1.5460032e+09 | H6: =G6*Parameters!$B$4 -> 40196084 | I6: =1/POWER(1+Parameters!$B$5, A6) -> 0.62092132 | J6: =H6*I6 -> 24958606 | K6: =SUM($G$2:G6) -> 7.7300162e+09 | L6: =F6*0.95 -> 917939.43 | M6: =L6*IF(E6="",Parameters!$B$2,E6) -> 1.4687031e+09 | N6: =M6*0.0251 -> 36864447 | O6: =N6*I6 -> 22889921
A7: 6 | B7: 19000000 | C7: 1.929 | D7: 0.82 | E7: 1600 | F7: =IFERROR(B7*C7*IF(D7="", Parameters!$B$2, D7)/Parameters!$B$6, 0) -> 966252.03 | G7: =F7*IF(E7="", Parameters!$B$2, E7) -> 1.5460032e+09 | H7: =G7*Parameters!$B$4 -> 40196084 | I7: =1/POWER(1+Parameters!$B$5, A7) -> 0.56447393 | J7: =H7*I7 -> 22689642 | K7: =SUM($G$2:G7) -> 9.2760195e+09 | L7: =F7*0.95 -> 917939.43 | M7: =L7*IF(E7="",Parameters!$B$2,E7) -> 1.4687031e+09 | N7: =M7*0.0251 -> 36864447 | O7: =N7*I7 -> 20809020
A8: 7 | B8: 19000000 | C8: 1.929 | D8: 0.82 | E8: 1600 | F8: =IFERROR(B8*C8*IF(D8="", Parameters!$B$2, D8)/Parameters!$B$6, 0) -> 966252.03 | G8: =F8*IF(E8="", Parameters!$B$2, E8) -> 1.5460032e+09 | H8: =G8*Parameters!$B$4 -> 40196084 | I8: =1/POWER(1+Parameters!$B$5, A8) -> 0.51315812 | J8: =H8*I8 -> 20626947 | K8: =SUM($G$2:G8) -> 1.0822023e+10 | L8: =F8*0.95 -> 917939.43 | M8: =L8*IF(E8="",Parameters!$B$2,E8) -> 1.4687031e+09 | N8: =M8*0.0251 -> 36864447 | O8: =N8*I8 -> 18917290
A9: 8 | B9: 19000000 | C9: 1.929 | D9: 0.82 | E9: 1600 | F9: =IFERROR(B9*C9*IF(D9="", Parameters!$B$2, D9)/Parameters!$B$6, 0) -> 966252.03 | G9: =F9*IF(E9="", Parameters!$B$2, E9) -> 1.5460032e+09 | H9: =G9*Parameters!$B$4 -> 40196084 | I9: =1/POWER(1+Parameters!$B$5, A9) -> 0.46650738 | J9: =H9*I9 -> 18751770 | K9: =SUM($G$2:G9) -> 1.2368026e+10 | L9: =F9*0.95 -> 917939.43 | M9: =L9*IF(E9="",Parameters!$B$2,E9) -> 1.4687031e+09 | N9: =M9*0.0251 -> 36864447 | O9: =N9*I9 -> 17197537
A10: 9 | B10: 19000000 | C10: 1.929 | D10: 0.82 | E10: 1600 | F10: =IFERROR(B10*C10*IF(D10="", Parameters!$B$2, D10)/Parameters!$B$6, 0) -> 966252.03 | G10: =F10*IF(E10="", Parameters!$B$2, E10) -> 1.5460032e+09 | H10: =G10*Parameters!$B$4 -> 40196084 | I10: =1/POWER(1+Parameters!$B$5, A10) -> 0.42409762 | J10: =H10*I10 -> 17047064 | K10: =SUM($G$2:G10) -> 1.3914029e+10 | L10: =F10*0.95 -> 917939.43 | M10: =L10*IF(E10="",Parameters!$B$2,E10) -> 1.4687031e+09 | N10: =M10*0.0251 -> 36864447 | O10: =N10*I10 -> 15634124
A11: 10 | B11: 19000000 | C11: 1.929 | D11: 0.82 | E11: 1600 | F11: =IFERROR(B11*C11*IF(D11="", Parameters!$B$2, D11)/Parameters!$B$6, 0) -> 966252.03 | G11: =F11*IF(E11="", Parameters!$B$2, E11) -> 1.5460032e+09 | H11: =G11*Parameters!$B$4 -> 40196084 | I11: =1/POWER(1+Parameters!$B$5, A11) -> 0.38554329 | J11: =H11*I11 -> 15497331 | K11: =SUM($G$2:G11) -> 1.5460032e+10 | L11: =F11*0.95 -> 917939.43 | M11: =L11*IF(E11="",Parameters!$B$2,E11) -> 1.4687031e+09 | N11: =M11*0.0251 -> 36864447 | O11: =N11*I11 -> 14212840
A12: 11 | B12: 19000000 | C12: 1.929 | D12: 0.82 | E12: 1600 | F12: =IFERROR(B12*C12*IF(D12="", Parameters!$B$2, D12)/Parameters!$B$6, 0) -> 966252.03 | G12: =F12*IF(E12="", Parameters!$B$2, E12) -> 1.5460032e+09 | H12: =G12*Parameters!$B$4 -> 40196084 | I12: =1/POWER(1+Parameters!$B$5, A12) -> 0.3504939 | J12: =H12*I12 -> 14088482 | K12: =SUM($G$2:G12) -> 1.7006036e+10 | L12: =F12*0.95 -> 917939.43 | M12: =L12*IF(E12="",Parameters!$B$2,E12) -> 1.4687031e+09 | N12: =M12*0.0251 -> 36864447 | O12: =N12*I12 -> 12920764
A13: 12 | B13: 19000000 | C13: 1.929 | D13: 0.82 | E13: 1600 | F13: =IFERROR(B13*C13*IF(D13="", Parameters!$B$2, D13)/Parameters!$B$6, 0) -> 966252.03 | G13: =F13*IF(E13="", Parameters!$B$2, E13) -> 1.5460032e+09 | H13: =G13*Parameters!$B$4 -> 40196084 | I13: =1/POWER(1+Parameters!$B$5, A13) -> 0.31863082 | J13: =H13*I13 -> 12807711 | K13: =SUM($G$2:G13) -> 1.8552039e+10 | L13: =F13*0.95 -> 917939.43 | M13: =L13*IF(E13="",Parameters!$B$2,E13) -> 1.4687031e+09 | N13: =M13*0.0251 -> 36864447 | O13: =N13*I13 -> 11746149
... A27: 26 | B27: 19000000 | C27: 1.929 | D27: 0.82 | E27: 1600 | F27: =IFERROR(B27*C27*IF(D27="", Parameters!$B$2, D27)/Parameters!$B$6, 0) -> 966252.03 | G27: =F27*IF(E27="", Parameters!$B$2, E27) -> 1.5460032e+09 | H27: =G27*Parameters!$B$4 -> 40196084 | I27: =1/POWER(1+Parameters!$B$5, A27) -> 0.083905453 | J27: =H27*I27 -> 3372670.7 | K27: =SUM($G$2:G27) -> 4.0196084e+10 | L27: =F27*0.95 -> 917939.43 | M27: =L27*IF(E27="",Parameters!$B$2,E27) -> 1.4687031e+09 | N27: =M27*0.0251 -> 36864447 | O27: =N27*I27 -> 3093128.2
F39: Totals / Key Outputs | G39: =SUM(G2:G33) -> 4.0196084e+10 | H39: =SUM(H2:H33) -> 1.0450982e+09 | J39: =SUM(J2:J27) -> 3.6823414e+08 | O39: =SUM(O2:O27) -> 3.3771319e+08
F40: Total Revenue (USD) | G40: =G39 -> 4.0196084e+10
F41: Total Severance Tax (USD) | G41: =H39 -> 1.0450982e+09
F42: PV(Severance Tax) (USD) | G42: =J39 -> 3.6823414e+08

Sheet schedule_8
A1: Year | B1: Ore (t) | C1: Grade (g/t) | D1: Recovery (override, optional) | E1: Metal Price (override, optional) | F1: Metal Produced (oz) | G1: Revenue (USD) | H1: Severance Tax (USD) | I1: Discount Factor | J1: PV(Severance Tax) (USD) | K1: Cumulative Revenue (USD) | L1: Payable Metal (oz) | M1: NSR ($) | N1: Royalty ($) | O1: PV(Royalty)
A2: 1 | B2: 16000000 | C2: 1.981 | D2: 0.82 | E2: 1600 | F2: =IFERROR(B2*C2*IF(D2="", Parameters!$B$2, D2)/Parameters!$B$6, 0) -> 835620.43 | G2: =F2*IF(E2="", Parameters!$B$2, E2) -> 1.3369927e+09 | H2: =G2*Parameters!$B$4 -> 34761810 | I2: =1/POWER(1+Parameters!$B$5, A2) -> 0.90909091 | J2: =H2*I2 -> 31601645 | K2: =SUM($G$2:G2) -> 1.3369927e+09 | L2: =F2*0.95 -> 793839.41 | M2: =L2*IF(E2="",Parameters!$B$2,E2) -> 1.2701431e+09 | N2: =M2*0.0251 -> 31880591 | O2: =N2*I2 -> 28982355
A3: 2 | B3: 16000000 | C3: 1.981 | D3: 0.82 | E3: 1600 | F3: =IFERROR(B3*C3*IF(D3="", Parameters!$B$2, D3)/Parameters!$B$6, 0) -> 835620.43 | G3: =F3*IF(E3="", Parameters!$B$2, E3) -> 1.3369927e+09 | H3: =G3*Parameters!$B$4 -> 34761810 | I3: =1/POWER(1+Parameters!$B$5, A3) -> 0.82644628 | J3: =H3*I3 -> 28728768 | K3: =SUM($G$2:G3) -> 2.6739854e+09 | L3: =F3*0.95 -> 793839.41 | M3: =L3*IF(E3="",Parameters!$B$2,E3) -> 1.2701431e+09 | N3: =M3*0.0251 -> 31880591 | O3: =N3*I3 -> 26347596
A4: 3 | B4: 16000000 | C4: 1.981 | D4: 0.82 | E4: 1600 | F4: =IFERROR(B4*C4*IF(D4="", Parameters!$B$2, D4)/Parameters!$B$6, 0) -> 835620.43 | G4: =F4*IF(E4="", Parameters!$B$2, E4) -> 1.3369927e+09 | H4: =G4*Parameters!$B$4 -> 34761810 | I4: =1/POWER(1+Parameters!$B$5, A4) -> 0.7513148 | J4: =H4*I4 -> 26117062 | K4: =SUM($G$2:G4) -> 4.0109781e+09 | L4: =F4*0.95 -> 793839.41 | M4: =L4*IF(E4="",Parameters!$B$2,E4) -> 1.2701431e+09 | N4: =M4*0.0251 -> 31880591 | O4: =N4*I4 -> 23952360
A5: 4 | B5: 16000000 | C5: 1.981 | D5: 0.82 | E5: 1600 | F5: =IFERROR(B5*C5*IF(D5="", Parameters!$B$2, D5)/Parameters!$B$6, 0) -> 835620.43 | G5: =F5*IF(E5="", Parameters!$B$2, E5) -> 1.3369927e+09 | H5: =G5*Parameters!$B$4 -> 34761810 | I5: =1/POWER(1+Parameters!$B$5, A5) -> 0.68301346 | J5: =H5*I5 -> 23742784 | K5: =SUM($G$2:G5) -> 5.3479707e+09 | L5: =F5*0.95 -> 793839.41 | M5: =L5*IF(E5="",Parameters!$B$2,E5) -> 1.2701431e+09 | N5: =M5*0.0251 -> 31880591 | O5: =N5*I5 -> 21774872
A6: 5 | B6: 16000000 | C6: 1.981 | D6: 0.82 | E6: 1600 | F6: =IFERROR(B6*C6*IF(D6="", Parameters!$B$2, D6)/Parameters!$B$6, 0) -> 835620.43 | G6: =F6*IF(E6="", Parameters!$B$2, E6) -> 1.3369927e+09 | H6: =G6*Parameters!$B$4 -> 34761810 | I6: =1/POWER(1+Parameters!$B$5, A6) -> 0.62092132 | J6: =H6*I6 -> 21584349 | K6: =SUM($G$2:G6) -> 6.6849634e+09 | L6: =F6*0.95 -> 793839.41 | M6: =L6*IF(E6="",Parameters!$B$2,E6) -> 1.2701431e+09 | N6: =M6*0.0251 -> 31880591 | O6: =N6*I6 -> 19795338
A7: 6 | B7: 16000000 | C7: 1.981 | D7: 0.82 | E7: 1600 | F7: =IFERROR(B7*C7*IF(D7="", Parameters!$B$2, D7)/Parameters!$B$6, 0) -> 835620.43 | G7: =F7*IF(E7="", Parameters!$B$2, E7) -> 1.3369927e+09 | H7: =G7*Parameters!$B$4 -> 34761810 | I7: =1/POWER(1+Parameters!$B$5, A7) -> 0.56447393 | J7: =H7*I7 -> 19622135 | K7: =SUM($G$2:G7) -> 8.0219561e+09 | L7: =F7*0.95 -> 793839.41 | M7: =L7*IF(E7="",Parameters!$B$2,E7) -> 1.2701431e+09 | N7: =M7*0.0251 -> 31880591 | O7: =N7*I7 -> 17995762
A8: 7 | B8: 16000000 | C8: 1.981 | D8: 0.82 | E8: 1600 | F8: =IFERROR(B8*C8*IF(D8="", Parameters!$B$2, D8)/Parameters!$B$6, 0) -> 835620.43 | G8: =F8*IF(E8="", Parameters!$B$2, E8) -> 1.3369927e+09 | H8: =G8*Parameters!$B$4 -> 34761810 | I8: =1/POWER(1+Parameters!$B$5, A8) -> 0.51315812 | J8: =H8*I8 -> 17838305 | K8: =SUM($G$2:G8) -> 9.3589488e+09 | L8: =F8*0.95 -> 793839.41 | M8: =L8*IF(E8="",Parameters!$B$2,E8) -> 1.2701431e+09 | N8: =M8*0.0251 -> 31880591 | O8: =N8*I8 -> 16359784
A9: 8 | B9: 16000000 | C9: 1.981 | D9: 0.82 | E9: 1600 | F9: =IFERROR(B9*C9*IF(D9="", Parameters!$B$2, D9)/Parameters!$B$6, 0) -> 835620.43 | G9: =F9*IF(E9="", Parameters!$B$2, E9) -> 1.3369927e+09 | H9: =G9*Parameters!$B$4 -> 34761810 | I9: =1/POWER(1+Parameters!$B$5, A9) -> 0.46650738 | J9: =H9*I9 -> 16216641 | K9: =SUM($G$2:G9) -> 1.0695941e+10 | L9: =F9*0.95 -> 793839.41 | M9: =L9*IF(E9="",Parameters!$B$2,E9) -> 1.2701431e+09 | N9: =M9*0.0251 -> 31880591 | O9: =N9*I9 -> 14872531
A10: 9 | B10: 16000000 | C10: 1.981 | D10: 0.82 | E10: 1600 | F10: =IFERROR(B10*C10*IF(D10="", Parameters!$B$2, D10)/Parameters!$B$6, 0) -> 835620.43 | G10: =F10*IF(E10="", Parameters!$B$2, E10) -> 1.3369927e+09 | H10: =G10*Parameters!$B$4 -> 34761810 | I10: =1/POWER(1+Parameters!$B$5, A10) -> 0.42409762 | J10: =H10*I10 -> 14742401 | K10: =SUM($G$2:G10) -> 1.2032934e+10 | L10: =F10*0.95 -> 793839.41 | M10: =L10*IF(E10="",Parameters!$B$2,E10) -> 1.2701431e+09 | N10: =M10*0.0251 -> 31880591 | O10: =N10*I10 -> 13520483
A11: 10 | B11: 16000000 | C11: 1.981 | D11: 0.82 | E11: 1600 | F11: =IFERROR(B11*C11*IF(D11="", Parameters!$B$2, D11)/Parameters!$B$6, 0) -> 835620.43 | G11: =F11*IF(E11="", Parameters!$B$2, E11) -> 1.3369927e+09 | H11: =G11*Parameters!$B$4 -> 34761810 | I11: =1/POWER(1+Parameters!$B$5, A11) -> 0.38554329 | J11: =H11*I11 -> 13402183 | K11: =SUM($G$2:G11) -> 1.3369927e+10 | L11: =F11*0.95 -> 793839.41 | M11: =L11*IF(E11="",Parameters!$B$2,E11) -> 1.2701431e+09 | N11: =M11*0.0251 -> 31880591 | O11: =N11*I11 -> 12291348
A12: 11 | B12: 16000000 | C12: 1.981 | D12: 0.82 | E12: 1600 | F12: =IFERROR(B12*C12*IF(D12="", Parameters!$B$2, D12)/Parameters!$B$6, 0) -> 835620.43 | G12: =F12*IF(E12="", Parameters!$B$2, E12) -> 1.3369927e+09 | H12: =G12*Parameters!$B$4 -> 34761810 | I12: =1/POWER(1+Parameters!$B$5, A12) -> 0.3504939 | J12: =H12*I12 -> 12183802 | K12: =SUM($G$2:G12) -> 1.470692e+10 | L12: =F12*0.95 -> 793839.41 | M12: =L12*IF(E12="",Parameters!$B$2,E12) -> 1.2701431e+09 | N12: =M12*0.0251 -> 31880591 | O12: =N12*I12 -> 11173953
A13: 12 | B13: 16000000 | C13: 1.981 | D13: 0.82 | E13: 1600 | F13: =IFERROR(B13*C13*IF(D13="", Parameters!$B$2, D13)/Parameters!$B$6, 0) -> 835620.43 | G13: =F13*IF(E13="", Parameters!$B$2, E13) -> 1.3369927e+09 | H13: =G13*Parameters!$B$4 -> 34761810 | I13: =1/POWER(1+Parameters!$B$5, A13) -> 0.31863082 | J13: =H13*I13 -> 11076184 | K13: =SUM($G$2:G13) -> 1.6043912e+10 | L13: =F13*0.95 -> 793839.41 | M13: =L13*IF(E13="",Parameters!$B$2,E13) -> 1.2701431e+09 | N13: =M13*0.0251 -> 31880591 | O13: =N13*I13 -> 10158139
... A29: 28 | B29: 16000000 | C29: 1.981 | D29: 0.82 | E29: 1600 | F29: =IFERROR(B29*C29*IF(D29="", Parameters!$B$2, D29)/Parameters!$B$6, 0) -> 835620.43 | G29: =F29*IF(E29="", Parameters!$B$2, E29) -> 1.3369927e+09 | H29: =G29*Parameters!$B$4 -> 34761810 | I29: =1/POWER(1+Parameters!$B$5, A29) -> 0.069343349 | J29: =H29*I29 -> 2410500.3 | K29: =SUM($G$2:G29) -> 3.7435795e+10 | L29: =F29*0.95 -> 793839.41 | M29: =L29*IF(E29="",Parameters!$B$2,E29) -> 1.2701431e+09 | N29: =M29*0.0251 -> 31880591 | O29: =N29*I29 -> 2210706.9
F39: Totals / Key Outputs | G39: =SUM(G2:G33) -> 3.7435795e+10 | H39: =SUM(H2:H33) -> 9.7333068e+08 | J39: =SUM(J2:J29) -> 3.235131e+08 | O39: =SUM(O2:O29) -> 2.9669884e+08
F40: Total Revenue (USD) | G40: =G39 -> 3.7435795e+10
F41: Total Severance Tax (USD) | G41: =H39 -> 9.7333068e+08
F42: PV(Severance Tax) (USD) | G42: =J39 -> 3.235131e+08

Sheet schedule_9
A1: Year | B1: Ore (t) | C1: Grade (g/t) | D1: Recovery (override, optional) | E1: Metal Price (override, optional) | F1: Metal Produced (oz) | G1: Revenue (USD) | H1: Severance Tax (USD) | I1: Discount Factor | J1: PV(Severance Tax) (USD) | K1: Cumulative Revenue (USD) | L1: Payable Metal (oz) | M1: NSR ($) | N1: Royalty ($) | O1: PV(Royalty)
A2: 1 | B2: 17000000 | C2: 1.928 | D2: 0.82 | E2: 1600 | F2: =IFERROR(B2*C2*IF(D2="", Parameters!$B$2, D2)/Parameters!$B$6, 0) -> 864093.11 | G2: =F2*IF(E2="", Parameters!$B$2, E2) -> 1.382549e+09 | H2: =G2*Parameters!$B$4 -> 35946273 | I2: =1/POWER(1+Parameters!$B$5, A2) -> 0.90909091 | J2: =H2*I2 -> 32678430 | K2: =SUM($G$2:G2) -> 1.382549e+09 | L2: =F2*0.95 -> 820888.45 | M2: =L2*IF(E2="",Parameters!$B$2,E2) -> 1.3134215e+09 | N2: =M2*0.0251 -> 32966880 | O2: =N2*I2 -> 29969891
A3: 2 | B3: 17000000 | C3: 1.928 | D3: 0.82 | E3: 1600 | F3: =IFERROR(B3*C3*IF(D3="", Parameters!$B$2, D3)/Parameters!$B$6, 0) -> 864093.11 | G3: =F3*IF(E3="", Parameters!$B$2, E3) -> 1.382549e+09 | H3: =G3*Parameters!$B$4 -> 35946273 | I3: =1/POWER(1+Parameters!$B$5, A3) -> 0.82644628 | J3: =H3*I3 -> 29707664 | K3: =SUM($G$2:G3) -> 2.7650979e+09 | L3: =F3*0.95 -> 820888.45 | M3: =L3*IF(E3="",Parameters!$B$2,E3) -> 1.3134215e+09 | N3: =M3*0.0251 -> 32966880 | O3: =N3*I3 -> 27245356
A4: 3 | B4: 17000000 | C4: 1.928 | D4: 0.82 | E4: 1600 | F4: =IFERROR(B4*C4*IF(D4="", Parameters!$B$2, D4)/Parameters!$B$6, 0) -> 864093.11 | G4: =F4*IF(E4="", Parameters!$B$2, E4) -> 1.382549e+09 | H4: =G4*Parameters!$B$4 -> 35946273 | I4: =1/POWER(1+Parameters!$B$5, A4) -> 0.7513148 | J4: =H4*I4 -> 27006967 | K4: =SUM($G$2:G4) -> 4.1476469e+09 | L4: =F4*0.95 -> 820888.45 | M4: =L4*IF(E4="",Parameters!$B$2,E4) -> 1.3134215e+09 | N4: =M4*0.0251 -> 32966880 | O4: =N4*I4 -> 24768505
